Workbook

Sheet ReadMe
A1: NFL MODEL 2026 - Read Me
A4: WHAT THIS IS
A5: A live-formula NFL game model. Attack and Defense ratings set each team's expected score;
A6: a five-statistic regression gives a second opinion; 3,000 simulated possessions per game turn
A7: those expectations into a distribution you can price a Moneyline, Spread and Total against.
A9: Built from two published methods:
A10: Excel LADZ, 'Building an NFL Model' Parts 1-3 - ratings, scoreline simulation, overtime, pricing
A11: Samford Sports Analytics, 'How I Built a Competitive NFL Prediction Model with Only Five
A12: Statistics' - regression on passing yards, rushing yards, takeaways and giveaways
A14: COLOUR LEGEND
A15: BLUE text on YELLOW fill = you type here. Nothing else should ever be overtyped.
A16: Black text = a formula. Green text = a value pulled from another sheet.
... A48: For research and entertainment. Bet only what you can afford to lose, if at all.

Sheet Teams
A1: TEAM INPUTS - per-game rates
A2: Overtype the yellow block only. Columns L:N are calculated. Rank 1 = best.
A4: Team | B4: G | C4: PF/g | D4: PA/g | E4: PassYds For/g | F4: PassYds Ag/g | G4: RushYds For/g | H4: RushYds Ag/g | I4: Giveaways/g | J4: Takeaways/g | L4: ATT | M4: DEF | N4: Power (pts)
A5: ARI | B5: 17 | C5: 24.2 | D5: 21 | E5: 231 | F5: 218 | G5: 118 | H5: 109 | I5: 1.24 | J5: 1.35 | L5: =IFERROR(C5/$C$38,1) -> 1 | M5: =IFERROR(D5/$D$38,1) -> 1 | N5: =(L5-M5)*$C$38 -> 0
A6: ATL | B6: 17 | C6: 24.2 | D6: 21 | E6: 231 | F6: 218 | G6: 118 | H6: 109 | I6: 1.24 | J6: 1.35 | L6: =IFERROR(C6/$C$38,1) -> 1 | M6: =IFERROR(D6/$D$38,1) -> 1 | N6: =(L6-M6)*$C$38 -> 0
A7: BAL | B7: 17 | C7: 24.2 | D7: 21 | E7: 231 | F7: 218 | G7: 118 | H7: 109 | I7: 1.24 | J7: 1.35 | L7: =IFERROR(C7/$C$38,1) -> 1 | M7: =IFERROR(D7/$D$38,1) -> 1 | N7: =(L7-M7)*$C$38 -> 0
A8: BUF | B8: 17 | C8: 24.2 | D8: 21 | E8: 231 | F8: 218 | G8: 118 | H8: 109 | I8: 1.24 | J8: 1.35 | L8: =IFERROR(C8/$C$38,1) -> 1 | M8: =IFERROR(D8/$D$38,1) -> 1 | N8: =(L8-M8)*$C$38 -> 0
A9: CAR | B9: 17 | C9: 24.2 | D9: 21 | E9: 231 | F9: 218 | G9: 118 | H9: 109 | I9: 1.24 | J9: 1.35 | L9: =IFERROR(C9/$C$38,1) -> 1 | M9: =IFERROR(D9/$D$38,1) -> 1 | N9: =(L9-M9)*$C$38 -> 0
A10: CHI | B10: 17 | C10: 24.2 | D10: 21 | E10: 231 | F10: 218 | G10: 118 | H10: 109 | I10: 1.24 | J10: 1.35 | L10: =IFERROR(C10/$C$38,1) -> 1 | M10: =IFERROR(D10/$D$38,1) -> 1 | N10: =(L10-M10)*$C$38 -> 0
A11: CIN | B11: 17 | C11: 24.2 | D11: 21 | E11: 231 | F11: 218 | G11: 118 | H11: 109 | I11: 1.24 | J11: 1.35 | L11: =IFERROR(C11/$C$38,1) -> 1 | M11: =IFERROR(D11/$D$38,1) -> 1 | N11: =(L11-M11)*$C$38 -> 0
A12: CLE | B12: 17 | C12: 24.2 | D12: 21 | E12: 231 | F12: 218 | G12: 118 | H12: 109 | I12: 1.24 | J12: 1.35 | L12: =IFERROR(C12/$C$38,1) -> 1 | M12: =IFERROR(D12/$D$38,1) -> 1 | N12: =(L12-M12)*$C$38 -> 0
A13: DAL | B13: 17 | C13: 24.2 | D13: 21 | E13: 231 | F13: 218 | G13: 118 | H13: 109 | I13: 1.24 | J13: 1.35 | L13: =IFERROR(C13/$C$38,1) -> 1 | M13: =IFERROR(D13/$D$38,1) -> 1 | N13: =(L13-M13)*$C$38 -> 0
A14: DEN | B14: 17 | C14: 24.2 | D14: 21 | E14: 231 | F14: 218 | G14: 118 | H14: 109 | I14: 1.24 | J14: 1.35 | L14: =IFERROR(C14/$C$38,1) -> 1 | M14: =IFERROR(D14/$D$38,1) -> 1 | N14: =(L14-M14)*$C$38 -> 0
A15: DET | B15: 17 | C15: 24.2 | D15: 21 | E15: 231 | F15: 218 | G15: 118 | H15: 109 | I15: 1.24 | J15: 1.35 | L15: =IFERROR(C15/$C$38,1) -> 1 | M15: =IFERROR(D15/$D$38,1) -> 1 | N15: =(L15-M15)*$C$38 -> 0
A16: GB | B16: 17 | C16: 24.2 | D16: 21 | E16: 231 | F16: 218 | G16: 118 | H16: 109 | I16: 1.24 | J16: 1.35 | L16: =IFERROR(C16/$C$38,1) -> 1 | M16: =IFERROR(D16/$D$38,1) -> 1 | N16: =(L16-M16)*$C$38 -> 0
... A36: WAS | B36: 17 | C36: 24.2 | D36: 21 | E36: 231 | F36: 218 | G36: 118 | H36: 109 | I36: 1.24 | J36: 1.35 | L36: =IFERROR(C36/$C$38,1) -> 1 | M36: =IFERROR(D36/$D$38,1) -> 1 | N36: =(L36-M36)*$C$38 -> 0
A38: LEAGUE AVG | C38: =AVERAGE(C5:C36) -> 24.2 | D38: =AVERAGE(D5:D36) -> 21 | E38: =AVERAGE(E5:E36) -> 231 | F38: =AVERAGE(F5:F36) -> 218 | G38: =AVERAGE(G5:G36) -> 118 | H38: =AVERAGE(H5:H36) -> 109 | I38: =AVERAGE(I5:I36) -> 1.24 | J38: =AVERAGE(J5:J36) -> 1.35
A40: Source: user-entered from Pro Football Reference team stats. Row values above are placeholder examples - replace all 32 rows.
A41: ATT and DEF here are unadjusted for schedule. The Python engine solves them iteratively against opponent quality, which is materially better by mid-season.

Sheet Coefficients
A1: MODEL PARAMETERS
A2: Every number the model uses lives here. Yellow = editable.
A4: FIVE-STATISTIC REGRESSION (Samford)
A5: Intercept | B5: 2.2 | C5: Points = intercept + sum of the four terms below
A6: Coef: Passing Yards | B6: 0.065 | C6: about 6.5 points per 100 net passing yards
A7: Coef: Rushing Yards | B7: 0.055 | C7: about 5.5 points per 100 rushing yards
A8: Coef: Takeaways | B8: 1.6 | C8: each takeaway is worth roughly a point and a half
A9: Coef: Giveaways | B9: -2.1 | C9: giveaways cost more than takeaways gain - asymmetric
A10: SD: Passing Yards | B10: 66 | C10: game-to-game standard deviation, for the draws
A11: SD: Rushing Yards | B11: 44
A12: Residual SD (points) | B12: 6.8 | C12: the part of scoring the four stats do not explain
A13: Refit these each offseason: python nfl_model.py ratings --games games.csv
A15: GAME ENVIRONMENT
A16: League PPG (per team) | B16: =Teams!C38 -> 24.2 | C16: pulled from the Teams sheet average
A17: Home field advantage (pts) | B17: 1.9 | C17: NFL HFA has drifted down from ~2.6 to ~1.7-2.1. Set 0 for neutral sites.
A18: Bye-week bonus (pts) | B18: 0.6
A19: Short week penalty (pts) | B19: -0.5 | C19: Thursday off a Sunday
A20: Drives per team | B20: 11.2 | C20: possessions excluding kneeldowns
A21: SD of drives | B21: 1.15
A22: Environment SD | B22: 0.075 | C22: shared shock: weather, pace, shootout script. Makes the two scores correlate.
A24: SCORING RATES (per drive, league average offence)
A25: Base TD rate | B25: 0.235
A26: Base FG rate | B26: 0.135
A27: TD elasticity | B27: 1.35 | C27: good offences convert touchdowns; they do not merely kick more field goals
A28: FG elasticity | B28: 0.45
A29: Points per TD (with XP/2pt) | B29: 6.95 | C29: used by the ratings maths; the simulation resolves each conversion individually
A30: 2-point attempt rate | B30: 0.09
A31: 2-point success rate | B31: 0.48
A32: Extra point success rate | B32: 0.955
A34: ENSEMBLE AND STAKING
A35: Weight: Ratings model | B35: 0.55 | C35: the two weights should sum to 1
A36: Weight: Regression model | B36: 0.45
A37: Kelly fraction | B37: 0.25 | C37: quarter Kelly. Full Kelly will find your ruin.
A38: Max stake (% bankroll) | B38: 0.02
A39: Min edge to bet | B39: 0.025 | C39: model probability must beat the no-vig price by this much before anything fires
A40: Bankroll | B40: 1000

Sheet Matchup
A1: MATCHUP
A2: Choose two teams. Everything below recalculates.
A3: SELECT
A4: Home team | B4: KC | C4: dropdown
A5: Away team | B5: BUF | C5: dropdown
A6: Neutral site? (1 = yes) | B6: 0 | C6: kills home field advantage
A7: Home rest (0 norm/1 bye/-1 short) | B7: 0
A8: Away rest (0 norm/1 bye/-1 short) | B8: 0
A10: METHOD 1 - ATTACK / DEFENSE RATINGS (Excel LADZ)
A11: Home ATT | B11: =INDEX(Teams!$L$5:$L$36,MATCH($B$4,Teams!$A$5:$A$36,0)) -> 1
A12: Home DEF | B12: =INDEX(Teams!$M$5:$M$36,MATCH($B$4,Teams!$A$5:$A$36,0)) -> 1
A13: Away ATT | B13: =INDEX(Teams!$L$5:$L$36,MATCH($B$5,Teams!$A$5:$A$36,0)) -> 1
A14: Away DEF | B14: =INDEX(Teams!$M$5:$M$36,MATCH($B$5,Teams!$A$5:$A$36,0)) -> 1
A15: Ratings: home expected pts | B15: =Coefficients!$B$16*B11*B14 -> 24.2 | C15: league PPG x home attack x away defense
A16: Ratings: away expected pts | B16: =Coefficients!$B$16*B13*B12 -> 24.2
A18: METHOD 2 - FIVE STATISTICS (Samford)
B19: HOME | C19: AWAY | D19: how it is built
A20: Expected passing yards | B20: =AVERAGE(INDEX(Teams!$E$5:$E$36,MATCH($B$4,Teams!$A$5:$A$36,0)),INDEX(Teams!$F$5:$F$36,MATCH($B$5,Teams!$A$5:$A$36,0))) -> 224.5 | C20: =AVERAGE(INDEX(Teams!$E$5:$E$36,MATCH($B$5,Teams!$A$5:$A$36,0)),INDEX(Teams!$F$5:$F$36,MATCH($B$4,Teams!$A$5:$A$36,0))) -> 224.5 | D20: team's own passing rate blended with the opponent's rate allowed
A21: Expected rushing yards | B21: =AVERAGE(INDEX(Teams!$G$5:$G$36,MATCH($B$4,Teams!$A$5:$A$36,0)),INDEX(Teams!$H$5:$H$36,MATCH($B$5,Teams!$A$5:$A$36,0))) -> 113.5 | C21: =AVERAGE(INDEX(Teams!$G$5:$G$36,MATCH($B$5,Teams!$A$5:$A$36,0)),INDEX(Teams!$H$5:$H$36,MATCH($B$4,Teams!$A$5:$A$36,0))) -> 113.5 | D21: same blend, rushing
A22: Expected giveaways | B22: =AVERAGE(INDEX(Teams!$I$5:$I$36,MATCH($B$4,Teams!$A$5:$A$36,0)),INDEX(Teams!$J$5:$J$36,MATCH($B$5,Teams!$A$5:$A$36,0))) -> 1.295 | C22: =AVERAGE(INDEX(Teams!$I$5:$I$36,MATCH($B$5,Teams!$A$5:$A$36,0)),INDEX(Teams!$J$5:$J$36,MATCH($B$4,Teams!$A$5:$A$36,0))) -> 1.295 | D22: your giveaway rate against their takeaway rate
A23: Expected takeaways | B23: =AVERAGE(INDEX(Teams!$J$5:$J$36,MATCH($B$4,Teams!$A$5:$A$36,0)),INDEX(Teams!$I$5:$I$36,MATCH($B$5,Teams!$A$5:$A$36,0))) -> 1.295 | C23: =AVERAGE(INDEX(Teams!$J$5:$J$36,MATCH($B$5,Teams!$A$5:$A$36,0)),INDEX(Teams!$I$5:$I$36,MATCH($B$4,Teams!$A$5:$A$36,0))) -> 1.295 | D23: the mirror image
A24: Regression: expected pts | B24: =Coefficients!$B$5 + Coefficients!$B$6*B20 + Coefficients!$B$7*B21 + Coefficients!$B$8*B23 + Coefficients!$B$9*B22 -> 22.3875 | C24: =Coefficients!$B$5 + Coefficients!$B$6*C20 + Coefficients!$B$7*C21 + Coefficients!$B$8*C23 + Coefficients!$B$9*C22 -> 22.3875
A26: BLEND + SITUATIONAL ADJUSTMENTS
A27: Home field / rest adjustment | B27: =IF($B$6=1,0,Coefficients!$B$17/2)+IF($B$7=1,Coefficients!$B$18/2,IF($B$7=-1,Coefficients!$B$19/2,0)) -> 0.95 | C27: =IF($B$6=1,0,-Coefficients!$B$17/2)+IF($B$8=1,Coefficients!$B$18/2,IF($B$8=-1,Coefficients!$B$19/2,0)) -> -0.95
A28: EXPECTED SCORE | B28: =MAX(6,(Coefficients!$B$35*B15+Coefficients!$B$36*B24)/(Coefficients!$B$35+Coefficients!$B$36)+B27) -> 24.334375 | C28: =MAX(6,(Coefficients!$B$35*B16+Coefficients!$B$36*C24)/(Coefficients!$B$35+Coefficients!$B$36)+C27) -> 22.434375
A29: Model spread (home) | B29: =-(B28-C28) -> -1.9
A30: Model total | B30: =B28+C28 -> 46.76875
A32: DRIVE-LEVEL SCORING RATES (feeds the simulation)
A33: Expected points converted into per-possession touchdown and field goal rates, then rescaled so the rates reproduce the expected score exactly.
B34: HOME | C34: AWAY
A35: Scoring index k | B35: =B28/(Coefficients!$B$20*(Coefficients!$B$25*Coefficients!$B$29+Coefficients!$B$26*3)) -> 1.0659694 | C35: =C28/(Coefficients!$B$20*(Coefficients!$B$25*Coefficients!$B$29+Coefficients!$B$26*3)) -> 0.9827397
A36: Raw TD rate | B36: =Coefficients!$B$25*B35^Coefficients!$B$27 -> 0.25616703 | C36: =Coefficients!$B$25*C35^Coefficients!$B$27 -> 0.22954077
A37: Raw FG rate | B37: =Coefficients!$B$26*B35^Coefficients!$B$28 -> 0.13893731 | C37: =Coefficients!$B$26*C35^Coefficients!$B$28 -> 0.13394641
A38: Scale to hit expected pts | B38: =(B28/Coefficients!$B$20)/(B36*Coefficients!$B$29+B37*3) -> 0.98886717 | C38: =(C28/Coefficients!$B$20)/(C36*Coefficients!$B$29+C37*3) -> 1.002965
A39: TD rate per drive | B39: =MIN(0.7,B36*B38) -> 0.25331517 | C39: =MIN(0.7,C36*C38) -> 0.23022137
A40: FG rate per drive | B40: =MIN(0.4,B37*B38) -> 0.13739055 | C40: =MIN(0.4,C37*C38) -> 0.13434357
A42: SIMULATION OUTPUT
A43: P(home win) | B43: =Simulations!Z5 -> 0.55116667
A44: P(away win) | B44: =Simulations!Z6 -> 0.44883333
A45: P(tie) | B45: =Simulations!Z7 -> 0.016333333
...

Sheet Simulations
A1: SIMULATIONS - 3,000 games
A2: Volatile: every keystroke rerolls. The summary block in Y:AA is what the model prices off.
A3: Sim | B3: Env | C3: Drives | D3: H TD | E3: H 2pt att | F3: H 2pt made | G3: H XP miss | H3: H FG | I3: H Reg | J3: A TD | K3: A 2pt att | L3: A 2pt made | M3: A XP miss | N3: A FG | O3: A Reg | P3: otRH | Q3: otRA | R3: H OT | S3: A OT | T3: HOME | U3: AWAY | V3: Margin | W3: Total | Y3: SUMMARY | Z3: value
A4: 1 | B4: =NORMINV(RAND(),1,Coefficients!$B$22) -> 1.0877216 | C4: =MEDIAN(8,16,ROUND(NORMINV(RAND(),Coefficients!$B$20,Coefficients!$B$21),0)) -> 11 | D4: =CRITBINOM($C4,MIN(0.75,Matchup!$B$39*$B4),RAND()) -> 4 | E4: =CRITBINOM(D4,Coefficients!$B$30,RAND()) -> 0 | F4: =CRITBINOM(E4,Coefficients!$B$31,RAND()) -> 0 | G4: =CRITBINOM(MAX(0,D4-E4),1-Coefficients!$B$32,RAND()) -> 0 | H4: =CRITBINOM(MAX(0,$C4-D4),MIN(0.6,Matchup!$B$40*SQRT($B4)/(1-MIN(0.75,Matchup!$B$39*$B4))),RAND()) -> 2 | I4: =6*D4+(D4-E4-G4)+2*F4+3*H4 -> 34 | J4: =CRITBINOM($C4,MIN(0.75,Matchup!$C$39*$B4),RAND()) -> 2 | K4: =CRITBINOM(J4,Coefficients!$B$30,RAND()) -> 0 | L4: =CRITBINOM(K4,Coefficients!$B$31,RAND()) -> 0 | M4: =CRITBINOM(MAX(0,J4-K4),1-Coefficients!$B$32,RAND()) -> 0 | N4: =CRITBINOM(MAX(0,$C4-J4),MIN(0.6,Matchup!$C$40*SQRT($B4)/(1-MIN(0.75,Matchup!$C$39*$B4))),RAND()) -> 1 | O4: =6*J4+(J4-K4-M4)+2*L4+3*N4 -> 17 | P4: =RAND() -> 0.39575554 | Q4: =RAND() -> 0.50407723 | R4: =IF($I4<>$O4,0,IF(P4<Matchup!$B$39,7,IF(P4<Matchup!$B$39+Matchup!$B$40,3,0))) -> 0 | S4: =IF($I4<>$O4,0,IF(Q4<Matchup!$C$39,7,IF(Q4<Matchup!$C$39+Matchup!$C$40,3,0))) -> 0 | T4: =I4+R4 -> 34 | U4: =O4+S4 -> 17 | V4: =T4-U4 -> 17 | W4: =T4+U4 -> 51 | Y4: n | Z4: =COUNT(T4:T3003) -> 3000
A5: 2 | B5: =NORMINV(RAND(),1,Coefficients!$B$22) -> 1.0024323 | C5: =MEDIAN(8,16,ROUND(NORMINV(RAND(),Coefficients!$B$20,Coefficients!$B$21),0)) -> 13 | D5: =CRITBINOM($C5,MIN(0.75,Matchup!$B$39*$B5),RAND()) -> 5 | E5: =CRITBINOM(D5,Coefficients!$B$30,RAND()) -> 0 | F5: =CRITBINOM(E5,Coefficients!$B$31,RAND()) -> 0 | G5: =CRITBINOM(MAX(0,D5-E5),1-Coefficients!$B$32,RAND()) -> 0 | H5: =CRITBINOM(MAX(0,$C5-D5),MIN(0.6,Matchup!$B$40*SQRT($B5)/(1-MIN(0.75,Matchup!$B$39*$B5))),RAND()) -> 2 | I5: =6*D5+(D5-E5-G5)+2*F5+3*H5 -> 41 | J5: =CRITBINOM($C5,MIN(0.75,Matchup!$C$39*$B5),RAND()) -> 4 | K5: =CRITBINOM(J5,Coefficients!$B$30,RAND()) -> 1 | L5: =CRITBINOM(K5,Coefficients!$B$31,RAND()) -> 0 | M5: =CRITBINOM(MAX(0,J5-K5),1-Coefficients!$B$32,RAND()) -> 0 | N5: =CRITBINOM(MAX(0,$C5-J5),MIN(0.6,Matchup!$C$40*SQRT($B5)/(1-MIN(0.75,Matchup!$C$39*$B5))),RAND()) -> 3 | O5: =6*J5+(J5-K5-M5)+2*L5+3*N5 -> 36 | P5: =RAND() -> 0.7725344 | Q5: =RAND() -> 0.35023582 | R5: =IF($I5<>$O5,0,IF(P5<Matchup!$B$39,7,IF(P5<Matchup!$B$39+Matchup!$B$40,3,0))) -> 0 | S5: =IF($I5<>$O5,0,IF(Q5<Matchup!$C$39,7,IF(Q5<Matchup!$C$39+Matchup!$C$40,3,0))) -> 0 | T5: =I5+R5 -> 41 | U5: =O5+S5 -> 36 | V5: =T5-U5 -> 5 | W5: =T5+U5 -> 77 | Y5: P(home win) | Z5: =(COUNTIF(V4:V3003,">0")+0.5*COUNTIF(V4:V3003,0))/$Z$4 -> 0.55116667
A6: 3 | B6: =NORMINV(RAND(),1,Coefficients!$B$22) -> 0.97647677 | C6: =MEDIAN(8,16,ROUND(NORMINV(RAND(),Coefficients!$B$20,Coefficients!$B$21),0)) -> 10 | D6: =CRITBINOM($C6,MIN(0.75,Matchup!$B$39*$B6),RAND()) -> 2 | E6: =CRITBINOM(D6,Coefficients!$B$30,RAND()) -> 0 | F6: =CRITBINOM(E6,Coefficients!$B$31,RAND()) -> 0 | G6: =CRITBINOM(MAX(0,D6-E6),1-Coefficients!$B$32,RAND()) -> 1 | H6: =CRITBINOM(MAX(0,$C6-D6),MIN(0.6,Matchup!$B$40*SQRT($B6)/(1-MIN(0.75,Matchup!$B$39*$B6))),RAND()) -> 1 | I6: =6*D6+(D6-E6-G6)+2*F6+3*H6 -> 16 | J6: =CRITBINOM($C6,MIN(0.75,Matchup!$C$39*$B6),RAND()) -> 3 | K6: =CRITBINOM(J6,Coefficients!$B$30,RAND()) -> 1 | L6: =CRITBINOM(K6,Coefficients!$B$31,RAND()) -> 0 | M6: =CRITBINOM(MAX(0,J6-K6),1-Coefficients!$B$32,RAND()) -> 0 | N6: =CRITBINOM(MAX(0,$C6-J6),MIN(0.6,Matchup!$C$40*SQRT($B6)/(1-MIN(0.75,Matchup!$C$39*$B6))),RAND()) -> 3 | O6: =6*J6+(J6-K6-M6)+2*L6+3*N6 -> 29 | P6: =RAND() -> 0.12850452 | Q6: =RAND() -> 0.88791122 | R6: =IF($I6<>$O6,0,IF(P6<Matchup!$B$39,7,IF(P6<Matchup!$B$39+Matchup!$B$40,3,0))) -> 0 | S6: =IF($I6<>$O6,0,IF(Q6<Matchup!$C$39,7,IF(Q6<Matchup!$C$39+Matchup!$C$40,3,0))) -> 0 | T6: =I6+R6 -> 16 | U6: =O6+S6 -> 29 | V6: =T6-U6 -> -13 | W6: =T6+U6 -> 45 | Y6: P(away win) | Z6: =(COUNTIF(V4:V3003,"<0")+0.5*COUNTIF(V4:V3003,0))/$Z$4 -> 0.44883333
A7: 4 | B7: =NORMINV(RAND(),1,Coefficients!$B$22) -> 1.0577049 | C7: =MEDIAN(8,16,ROUND(NORMINV(RAND(),Coefficients!$B$20,Coefficients!$B$21),0)) -> 9 | D7: =CRITBINOM($C7,MIN(0.75,Matchup!$B$39*$B7),RAND()) -> 1 | E7: =CRITBINOM(D7,Coefficients!$B$30,RAND()) -> 0 | F7: =CRITBINOM(E7,Coefficients!$B$31,RAND()) -> 0 | G7: =CRITBINOM(MAX(0,D7-E7),1-Coefficients!$B$32,RAND()) -> 0 | H7: =CRITBINOM(MAX(0,$C7-D7),MIN(0.6,Matchup!$B$40*SQRT($B7)/(1-MIN(0.75,Matchup!$B$39*$B7))),RAND()) -> 3 | I7: =6*D7+(D7-E7-G7)+2*F7+3*H7 -> 16 | J7: =CRITBINOM($C7,MIN(0.75,Matchup!$C$39*$B7),RAND()) -> 1 | K7: =CRITBINOM(J7,Coefficients!$B$30,RAND()) -> 0 | L7: =CRITBINOM(K7,Coefficients!$B$31,RAND()) -> 0 | M7: =CRITBINOM(MAX(0,J7-K7),1-Coefficients!$B$32,RAND()) -> 0 | N7: =CRITBINOM(MAX(0,$C7-J7),MIN(0.6,Matchup!$C$40*SQRT($B7)/(1-MIN(0.75,Matchup!$C$39*$B7))),RAND()) -> 0 | O7: =6*J7+(J7-K7-M7)+2*L7+3*N7 -> 7 | P7: =RAND() -> 0.83994267 | Q7: =RAND() -> 0.32490219 | R7: =IF($I7<>$O7,0,IF(P7<Matchup!$B$39,7,IF(P7<Matchup!$B$39+Matchup!$B$40,3,0))) -> 0 | S7: =IF($I7<>$O7,0,IF(Q7<Matchup!$C$39,7,IF(Q7<Matchup!$C$39+Matchup!$C$40,3,0))) -> 0 | T7: =I7+R7 -> 16 | U7: =O7+S7 -> 7 | V7: =T7-U7 -> 9 | W7: =T7+U7 -> 23 | Y7: P(tie) | Z7: =COUNTIF(V4:V3003,0)/$Z$4 -> 0.016333333 | AA7: a tie pushes the moneyline
A8: 5 | B8: =NORMINV(RAND(),1,Coefficients!$B$22) -> 0.94159367 | C8: =MEDIAN(8,16,ROUND(NORMINV(RAND(),Coefficients!$B$20,Coefficients!$B$21),0)) -> 11 | D8: =CRITBINOM($C8,MIN(0.75,Matchup!$B$39*$B8),RAND()) -> 3 | E8: =CRITBINOM(D8,Coefficients!$B$30,RAND()) -> 0 | F8: =CRITBINOM(E8,Coefficients!$B$31,RAND()) -> 0 | G8: =CRITBINOM(MAX(0,D8-E8),1-Coefficients!$B$32,RAND()) -> 0 | H8: =CRITBINOM(MAX(0,$C8-D8),MIN(0.6,Matchup!$B$40*SQRT($B8)/(1-MIN(0.75,Matchup!$B$39*$B8))),RAND()) -> 2 | I8: =6*D8+(D8-E8-G8)+2*F8+3*H8 -> 27 | J8: =CRITBINOM($C8,MIN(0.75,Matchup!$C$39*$B8),RAND()) -> 1 | K8: =CRITBINOM(J8,Coefficients!$B$30,RAND()) -> 0 | L8: =CRITBINOM(K8,Coefficients!$B$31,RAND()) -> 0 | M8: =CRITBINOM(MAX(0,J8-K8),1-Coefficients!$B$32,RAND()) -> 0 | N8: =CRITBINOM(MAX(0,$C8-J8),MIN(0.6,Matchup!$C$40*SQRT($B8)/(1-MIN(0.75,Matchup!$C$39*$B8))),RAND()) -> 3 | O8: =6*J8+(J8-K8-M8)+2*L8+3*N8 -> 16 | P8: =RAND() -> 0.93802363 | Q8: =RAND() -> 0.65097789 | R8: =IF($I8<>$O8,0,IF(P8<Matchup!$B$39,7,IF(P8<Matchup!$B$39+Matchup!$B$40,3,0))) -> 0 | S8: =IF($I8<>$O8,0,IF(Q8<Matchup!$C$39,7,IF(Q8<Matchup!$C$39+Matchup!$C$40,3,0))) -> 0 | T8: =I8+R8 -> 27 | U8: =O8+S8 -> 16 | V8: =T8-U8 -> 11 | W8: =T8+U8 -> 43 | Y8: Mean home | Z8: =AVERAGE(T4:T3003) -> 24.384333
A9: 6 | B9: =NORMINV(RAND(),1,Coefficients!$B$22) -> 1.0277566 | C9: =MEDIAN(8,16,ROUND(NORMINV(RAND(),Coefficients!$B$20,Coefficients!$B$21),0)) -> 11 | D9: =CRITBINOM($C9,MIN(0.75,Matchup!$B$39*$B9),RAND()) -> 2 | E9: =CRITBINOM(D9,Coefficients!$B$30,RAND()) -> 1 | F9: =CRITBINOM(E9,Coefficients!$B$31,RAND()) -> 0 | G9: =CRITBINOM(MAX(0,D9-E9),1-Coefficients!$B$32,RAND()) -> 0 | H9: =CRITBINOM(MAX(0,$C9-D9),MIN(0.6,Matchup!$B$40*SQRT($B9)/(1-MIN(0.75,Matchup!$B$39*$B9))),RAND()) -> 1 | I9: =6*D9+(D9-E9-G9)+2*F9+3*H9 -> 16 | J9: =CRITBINOM($C9,MIN(0.75,Matchup!$C$39*$B9),RAND()) -> 4 | K9: =CRITBINOM(J9,Coefficients!$B$30,RAND()) -> 2 | L9: =CRITBINOM(K9,Coefficients!$B$31,RAND()) -> 1 | M9: =CRITBINOM(MAX(0,J9-K9),1-Coefficients!$B$32,RAND()) -> 0 | N9: =CRITBINOM(MAX(0,$C9-J9),MIN(0.6,Matchup!$C$40*SQRT($B9)/(1-MIN(0.75,Matchup!$C$39*$B9))),RAND()) -> 1 | O9: =6*J9+(J9-K9-M9)+2*L9+3*N9 -> 31 | P9: =RAND() -> 0.36622401 | Q9: =RAND() -> 0.34242266 | R9: =IF($I9<>$O9,0,IF(P9<Matchup!$B$39,7,IF(P9<Matchup!$B$39+Matchup!$B$40,3,0))) -> 0 | S9: =IF($I9<>$O9,0,IF(Q9<Matchup!$C$39,7,IF(Q9<Matchup!$C$39+Matchup!$C$40,3,0))) -> 0 | T9: =I9+R9 -> 16 | U9: =O9+S9 -> 31 | V9: =T9-U9 -> -15 | W9: =T9+U9 -> 47 | Y9: Mean away | Z9: =AVERAGE(U4:U3003) -> 22.407667
A10: 7 | B10: =NORMINV(RAND(),1,Coefficients!$B$22) -> 1.0021179 | C10: =MEDIAN(8,16,ROUND(NORMINV(RAND(),Coefficients!$B$20,Coefficients!$B$21),0)) -> 12 | D10: =CRITBINOM($C10,MIN(0.75,Matchup!$B$39*$B10),RAND()) -> 4 | E10: =CRITBINOM(D10,Coefficients!$B$30,RAND()) -> 1 | F10: =CRITBINOM(E10,Coefficients!$B$31,RAND()) -> 1 | G10: =CRITBINOM(MAX(0,D10-E10),1-Coefficients!$B$32,RAND()) -> 0 | H10: =CRITBINOM(MAX(0,$C10-D10),MIN(0.6,Matchup!$B$40*SQRT($B10)/(1-MIN(0.75,Matchup!$B$39*$B10))),RAND()) -> 2 | I10: =6*D10+(D10-E10-G10)+2*F10+3*H10 -> 35 | J10: =CRITBINOM($C10,MIN(0.75,Matchup!$C$39*$B10),RAND()) -> 2 | K10: =CRITBINOM(J10,Coefficients!$B$30,RAND()) -> 1 | L10: =CRITBINOM(K10,Coefficients!$B$31,RAND()) -> 0 | M10: =CRITBINOM(MAX(0,J10-K10),1-Coefficients!$B$32,RAND()) -> 0 | N10: =CRITBINOM(MAX(0,$C10-J10),MIN(0.6,Matchup!$C$40*SQRT($B10)/(1-MIN(0.75,Matchup!$C$39*$B10))),RAND()) -> 1 | O10: =6*J10+(J10-K10-M10)+2*L10+3*N10 -> 16 | P10: =RAND() -> 0.47051608 | Q10: =RAND() -> 0.52642221 | R10: =IF($I10<>$O10,0,IF(P10<Matchup!$B$39,7,IF(P10<Matchup!$B$39+Matchup!$B$40,3,0))) -> 0 | S10: =IF($I10<>$O10,0,IF(Q10<Matchup!$C$39,7,IF(Q10<Matchup!$C$39+Matchup!$C$40,3,0))) -> 0 | T10: =I10+R10 -> 35 | U10: =O10+S10 -> 16 | V10: =T10-U10 -> 19 | W10: =T10+U10 -> 51 | Y10: Mean margin | Z10: =AVERAGE(V4:V3003) -> 1.9766667 | AA10: positive = home favoured
A11: 8 | B11: =NORMINV(RAND(),1,Coefficients!$B$22) -> 1.0384054 | C11: =MEDIAN(8,16,ROUND(NORMINV(RAND(),Coefficients!$B$20,Coefficients!$B$21),0)) -> 10 | D11: =CRITBINOM($C11,MIN(0.75,Matchup!$B$39*$B11),RAND()) -> 3 | E11: =CRITBINOM(D11,Coefficients!$B$30,RAND()) -> 0 | F11: =CRITBINOM(E11,Coefficients!$B$31,RAND()) -> 0 | G11: =CRITBINOM(MAX(0,D11-E11),1-Coefficients!$B$32,RAND()) -> 0 | H11: =CRITBINOM(MAX(0,$C11-D11),MIN(0.6,Matchup!$B$40*SQRT($B11)/(1-MIN(0.75,Matchup!$B$39*$B11))),RAND()) -> 2 | I11: =6*D11+(D11-E11-G11)+2*F11+3*H11 -> 27 | J11: =CRITBINOM($C11,MIN(0.75,Matchup!$C$39*$B11),RAND()) -> 2 | K11: =CRITBINOM(J11,Coefficients!$B$30,RAND()) -> 0 | L11: =CRITBINOM(K11,Coefficients!$B$31,RAND()) -> 0 | M11: =CRITBINOM(MAX(0,J11-K11),1-Coefficients!$B$32,RAND()) -> 0 | N11: =CRITBINOM(MAX(0,$C11-J11),MIN(0.6,Matchup!$C$40*SQRT($B11)/(1-MIN(0.75,Matchup!$C$39*$B11))),RAND()) -> 2 | O11: =6*J11+(J11-K11-M11)+2*L11+3*N11 -> 20 | P11: =RAND() -> 0.70163126 | Q11: =RAND() -> 0.59600706 | R11: =IF($I11<>$O11,0,IF(P11<Matchup!$B$39,7,IF(P11<Matchup!$B$39+Matchup!$B$40,3,0))) -> 0 | S11: =IF($I11<>$O11,0,IF(Q11<Matchup!$C$39,7,IF(Q11<Matchup!$C$39+Matchup!$C$40,3,0))) -> 0 | T11: =I11+R11 -> 27 | U11: =O11+S11 -> 20 | V11: =T11-U11 -> 7 | W11: =T11+U11 -> 47 | Y11: SD margin | Z11: =STDEV(V4:V3003) -> 13.805638 | AA11: real NFL sits near 13.6
A12: 9 | B12: =NORMINV(RAND(),1,Coefficients!$B$22) -> 1.0024147 | C12: =MEDIAN(8,16,ROUND(NORMINV(RAND(),Coefficients!$B$20,Coefficients!$B$21),0)) -> 12 | D12: =CRITBINOM($C12,MIN(0.75,Matchup!$B$39*$B12),RAND()) -> 3 | E12: =CRITBINOM(D12,Coefficients!$B$30,RAND()) -> 1 | F12: =CRITBINOM(E12,Coefficients!$B$31,RAND()) -> 0 | G12: =CRITBINOM(MAX(0,D12-E12),1-Coefficients!$B$32,RAND()) -> 0 | H12: =CRITBINOM(MAX(0,$C12-D12),MIN(0.6,Matchup!$B$40*SQRT($B12)/(1-MIN(0.75,Matchup!$B$39*$B12))),RAND()) -> 1 | I12: =6*D12+(D12-E12-G12)+2*F12+3*H12 -> 23 | J12: =CRITBINOM($C12,MIN(0.75,Matchup!$C$39*$B12),RAND()) -> 2 | K12: =CRITBINOM(J12,Coefficients!$B$30,RAND()) -> 1 | L12: =CRITBINOM(K12,Coefficients!$B$31,RAND()) -> 0 | M12: =CRITBINOM(MAX(0,J12-K12),1-Coefficients!$B$32,RAND()) -> 0 | N12: =CRITBINOM(MAX(0,$C12-J12),MIN(0.6,Matchup!$C$40*SQRT($B12)/(1-MIN(0.75,Matchup!$C$39*$B12))),RAND()) -> 0 | O12: =6*J12+(J12-K12-M12)+2*L12+3*N12 -> 13 | P12: =RAND() -> 0.43331823 | Q12: =RAND() -> 0.57244199 | R12: =IF($I12<>$O12,0,IF(P12<Matchup!$B$39,7,IF(P12<Matchup!$B$39+Matchup!$B$40,3,0))) -> 0 | S12: =IF($I12<>$O12,0,IF(Q12<Matchup!$C$39,7,IF(Q12<Matchup!$C$39+Matchup!$C$40,3,0))) -> 0 | T12: =I12+R12 -> 23 | U12: =O12+S12 -> 13 | V12: =T12-U12 -> 10 | W12: =T12+U12 -> 36 | Y12: Mean total | Z12: =AVERAGE(W4:W3003) -> 46.792
A13: 10 | B13: =NORMINV(RAND(),1,Coefficients!$B$22) -> 0.97117832 | C13: =MEDIAN(8,16,ROUND(NORMINV(RAND(),Coefficients!$B$20,Coefficients!$B$21),0)) -> 12 | D13: =CRITBINOM($C13,MIN(0.75,Matchup!$B$39*$B13),RAND()) -> 0 | E13: =CRITBINOM(D13,Coefficients!$B$30,RAND()) -> 0 | F13: =CRITBINOM(E13,Coefficients!$B$31,RAND()) -> 0 | G13: =CRITBINOM(MAX(0,D13-E13),1-Coefficients!$B$32,RAND()) -> 0 | H13: =CRITBINOM(MAX(0,$C13-D13),MIN(0.6,Matchup!$B$40*SQRT($B13)/(1-MIN(0.75,Matchup!$B$39*$B13))),RAND()) -> 3 | I13: =6*D13+(D13-E13-G13)+2*F13+3*H13 -> 9 | J13: =CRITBINOM($C13,MIN(0.75,Matchup!$C$39*$B13),RAND()) -> 1 | K13: =CRITBINOM(J13,Coefficients!$B$30,RAND()) -> 0 | L13: =CRITBINOM(K13,Coefficients!$B$31,RAND()) -> 0 | M13: =CRITBINOM(MAX(0,J13-K13),1-Coefficients!$B$32,RAND()) -> 1 | N13: =CRITBINOM(MAX(0,$C13-J13),MIN(0.6,Matchup!$C$40*SQRT($B13)/(1-MIN(0.75,Matchup!$C$39*$B13))),RAND()) -> 2 | O13: =6*J13+(J13-K13-M13)+2*L13+3*N13 -> 12 | P13: =RAND() -> 0.72999036 | Q13: =RAND() -> 0.83283451 | R13: =IF($I13<>$O13,0,IF(P13<Matchup!$B$39,7,IF(P13<Matchup!$B$39+Matchup!$B$40,3,0))) -> 0 | S13: =IF($I13<>$O13,0,IF(Q13<Matchup!$C$39,7,IF(Q13<Matchup!$C$39+Matchup!$C$40,3,0))) -> 0 | T13: =I13+R13 -> 9 | U13: =O13+S13 -> 12 | V13: =T13-U13 -> -3 | W13: =T13+U13 -> 21 | Y13: SD total | Z13: =STDEV(W4:W3003) -> 14.764758 | AA13: real NFL sits near 13.9
A14: 11 | B14: =NORMINV(RAND(),1,Coefficients!$B$22) -> 0.94692058 | C14: =MEDIAN(8,16,ROUND(NORMINV(RAND(),Coefficients!$B$20,Coefficients!$B$21),0)) -> 12 | D14: =CRITBINOM($C14,MIN(0.75,Matchup!$B$39*$B14),RAND()) -> 1 | E14: =CRITBINOM(D14,Coefficients!$B$30,RAND()) -> 0 | F14: =CRITBINOM(E14,Coefficients!$B$31,RAND()) -> 0 | G14: =CRITBINOM(MAX(0,D14-E14),1-Coefficients!$B$32,RAND()) -> 0 | H14: =CRITBINOM(MAX(0,$C14-D14),MIN(0.6,Matchup!$B$40*SQRT($B14)/(1-MIN(0.75,Matchup!$B$39*$B14))),RAND()) -> 1 | I14: =6*D14+(D14-E14-G14)+2*F14+3*H14 -> 10 | J14: =CRITBINOM($C14,MIN(0.75,Matchup!$C$39*$B14),RAND()) -> 2 | K14: =CRITBINOM(J14,Coefficients!$B$30,RAND()) -> 1 | L14: =CRITBINOM(K14,Coefficients!$B$31,RAND()) -> 0 | M14: =CRITBINOM(MAX(0,J14-K14),1-Coefficients!$B$32,RAND()) -> 0 | N14: =CRITBINOM(MAX(0,$C14-J14),MIN(0.6,Matchup!$C$40*SQRT($B14)/(1-MIN(0.75,Matchup!$C$39*$B14))),RAND()) -> 4 | O14: =6*J14+(J14-K14-M14)+2*L14+3*N14 -> 25 | P14: =RAND() -> 0.67660576 | Q14: =RAND() -> 0.94271656 | R14: =IF($I14<>$O14,0,IF(P14<Matchup!$B$39,7,IF(P14<Matchup!$B$39+Matchup!$B$40,3,0))) -> 0 | S14: =IF($I14<>$O14,0,IF(Q14<Matchup!$C$39,7,IF(Q14<Matchup!$C$39+Matchup!$C$40,3,0))) -> 0 | T14: =I14+R14 -> 10 | U14: =O14+S14 -> 25 | V14: =T14-U14 -> -15 | W14: =T14+U14 -> 35 | Y14: Median margin | Z14: =MEDIAN(V4:V3003) -> 2
A15: 12 | B15: =NORMINV(RAND(),1,Coefficients!$B$22) -> 1.0116222 | C15: =MEDIAN(8,16,ROUND(NORMINV(RAND(),Coefficients!$B$20,Coefficients!$B$21),0)) -> 11 | D15: =CRITBINOM($C15,MIN(0.75,Matchup!$B$39*$B15),RAND()) -> 1 | E15: =CRITBINOM(D15,Coefficients!$B$30,RAND()) -> 0 | F15: =CRITBINOM(E15,Coefficients!$B$31,RAND()) -> 0 | G15: =CRITBINOM(MAX(0,D15-E15),1-Coefficients!$B$32,RAND()) -> 0 | H15: =CRITBINOM(MAX(0,$C15-D15),MIN(0.6,Matchup!$B$40*SQRT($B15)/(1-MIN(0.75,Matchup!$B$39*$B15))),RAND()) -> 3 | I15: =6*D15+(D15-E15-G15)+2*F15+3*H15 -> 16 | J15: =CRITBINOM($C15,MIN(0.75,Matchup!$C$39*$B15),RAND()) -> 3 | K15: =CRITBINOM(J15,Coefficients!$B$30,RAND()) -> 0 | L15: =CRITBINOM(K15,Coefficients!$B$31,RAND()) -> 0 | M15: =CRITBINOM(MAX(0,J15-K15),1-Coefficients!$B$32,RAND()) -> 1 | N15: =CRITBINOM(MAX(0,$C15-J15),MIN(0.6,Matchup!$C$40*SQRT($B15)/(1-MIN(0.75,Matchup!$C$39*$B15))),RAND()) -> 2 | O15: =6*J15+(J15-K15-M15)+2*L15+3*N15 -> 26 | P15: =RAND() -> 0.18699542 | Q15: =RAND() -> 0.40877205 | R15: =IF($I15<>$O15,0,IF(P15<Matchup!$B$39,7,IF(P15<Matchup!$B$39+Matchup!$B$40,3,0))) -> 0 | S15: =IF($I15<>$O15,0,IF(Q15<Matchup!$C$39,7,IF(Q15<Matchup!$C$39+Matchup!$C$40,3,0))) -> 0 | T15: =I15+R15 -> 16 | U15: =O15+S15 -> 26 | V15: =T15-U15 -> -10 | W15: =T15+U15 -> 42
A16: 13 | B16: =NORMINV(RAND(),1,Coefficients!$B$22) -> 0.99825404 | C16: =MEDIAN(8,16,ROUND(NORMINV(RAND(),Coefficients!$B$20,Coefficients!$B$21),0)) -> 10 | D16: =CRITBINOM($C16,MIN(0.75,Matchup!$B$39*$B16),RAND()) -> 6 | E16: =CRITBINOM(D16,Coefficients!$B$30,RAND()) -> 0 | F16: =CRITBINOM(E16,Coefficients!$B$31,RAND()) -> 0 | G16: =CRITBINOM(MAX(0,D16-E16),1-Coefficients!$B$32,RAND()) -> 2 | H16: =CRITBINOM(MAX(0,$C16-D16),MIN(0.6,Matchup!$B$40*SQRT($B16)/(1-MIN(0.75,Matchup!$B$39*$B16))),RAND()) -> 1 | I16: =6*D16+(D16-E16-G16)+2*F16+3*H16 -> 43 | J16: =CRITBINOM($C16,MIN(0.75,Matchup!$C$39*$B16),RAND()) -> 4 | K16: =CRITBINOM(J16,Coefficients!$B$30,RAND()) -> 0 | L16: =CRITBINOM(K16,Coefficients!$B$31,RAND()) -> 0 | M16: =CRITBINOM(MAX(0,J16-K16),1-Coefficients!$B$32,RAND()) -> 0 | N16: =CRITBINOM(MAX(0,$C16-J16),MIN(0.6,Matchup!$C$40*SQRT($B16)/(1-MIN(0.75,Matchup!$C$39*$B16))),RAND()) -> 1 | O16: =6*J16+(J16-K16-M16)+2*L16+3*N16 -> 31 | P16: =RAND() -> 0.64725068 | Q16: =RAND() -> 0.22577649 | R16: =IF($I16<>$O16,0,IF(P16<Matchup!$B$39,7,IF(P16<Matchup!$B$39+Matchup!$B$40,3,0))) -> 0 | S16: =IF($I16<>$O16,0,IF(Q16<Matchup!$C$39,7,IF(Q16<Matchup!$C$39+Matchup!$C$40,3,0))) -> 0 | T16: =I16+R16 -> 43 | U16: =O16+S16 -> 31 | V16: =T16-U16 -> 12 | W16: =T16+U16 -> 74 | Y16: KEY NUMBERS
A17: 14 | B17: =NORMINV(RAND(),1,Coefficients!$B$22) -> 0.92266324 | C17: =MEDIAN(8,16,ROUND(NORMINV(RAND(),Coefficients!$B$20,Coefficients!$B$21),0)) -> 13 | D17: =CRITBINOM($C17,MIN(0.75,Matchup!$B$39*$B17),RAND()) -> 3 | E17: =CRITBINOM(D17,Coefficients!$B$30,RAND()) -> 0 | F17: =CRITBINOM(E17,Coefficients!$B$31,RAND()) -> 0 | G17: =CRITBINOM(MAX(0,D17-E17),1-Coefficients!$B$32,RAND()) -> 0 | H17: =CRITBINOM(MAX(0,$C17-D17),MIN(0.6,Matchup!$B$40*SQRT($B17)/(1-MIN(0.75,Matchup!$B$39*$B17))),RAND()) -> 3 | I17: =6*D17+(D17-E17-G17)+2*F17+3*H17 -> 30 | J17: =CRITBINOM($C17,MIN(0.75,Matchup!$C$39*$B17),RAND()) -> 2 | K17: =CRITBINOM(J17,Coefficients!$B$30,RAND()) -> 0 | L17: =CRITBINOM(K17,Coefficients!$B$31,RAND()) -> 0 | M17: =CRITBINOM(MAX(0,J17-K17),1-Coefficients!$B$32,RAND()) -> 0 | N17: =CRITBINOM(MAX(0,$C17-J17),MIN(0.6,Matchup!$C$40*SQRT($B17)/(1-MIN(0.75,Matchup!$C$39*$B17))),RAND()) -> 2 | O17: =6*J17+(J17-K17-M17)+2*L17+3*N17 -> 20 | P17: =RAND() -> 0.49108664 | Q17: =RAND() -> 0.73519664 | R17: =IF($I17<>$O17,0,IF(P17<Matchup!$B$39,7,IF(P17<Matchup!$B$39+Matchup!$B$40,3,0))) -> 0 | S17: =IF($I17<>$O17,0,IF(Q17<Matchup!$C$39,7,IF(Q17<Matchup!$C$39+Matchup!$C$40,3,0))) -> 0 | T17: =I17+R17 -> 30 | U17: =O17+S17 -> 20 | V17: =T17-U17 -> 10 | W17: =T17+U17 -> 50 | Y17: margin | Z17: model | AA17: real NFL, 2010-2025
A18: 15 | B18: =NORMINV(RAND(),1,Coefficients!$B$22) -> 0.95100456 | C18: =MEDIAN(8,16,ROUND(NORMINV(RAND(),Coefficients!$B$20,Coefficients!$B$21),0)) -> 12 | D18: =CRITBINOM($C18,MIN(0.75,Matchup!$B$39*$B18),RAND()) -> 4 | E18: =CRITBINOM(D18,Coefficients!$B$30,RAND()) -> 1 | F18: =CRITBINOM(E18,Coefficients!$B$31,RAND()) -> 1 | G18: =CRITBINOM(MAX(0,D18-E18),1-Coefficients!$B$32,RAND()) -> 0 | H18: =CRITBINOM(MAX(0,$C18-D18),MIN(0.6,Matchup!$B$40*SQRT($B18)/(1-MIN(0.75,Matchup!$B$39*$B18))),RAND()) -> 3 | I18: =6*D18+(D18-E18-G18)+2*F18+3*H18 -> 38 | J18: =CRITBINOM($C18,MIN(0.75,Matchup!$C$39*$B18),RAND()) -> 3 | K18: =CRITBINOM(J18,Coefficients!$B$30,RAND()) -> 0 | L18: =CRITBINOM(K18,Coefficients!$B$31,RAND()) -> 0 | M18: =CRITBINOM(MAX(0,J18-K18),1-Coefficients!$B$32,RAND()) -> 0 | N18: =CRITBINOM(MAX(0,$C18-J18),MIN(0.6,Matchup!$C$40*SQRT($B18)/(1-MIN(0.75,Matchup!$C$39*$B18))),RAND()) -> 1 | O18: =6*J18+(J18-K18-M18)+2*L18+3*N18 -> 24 | P18: =RAND() -> 0.6212906 | Q18: =RAND() -> 0.89252481 | R18: =IF($I18<>$O18,0,IF(P18<Matchup!$B$39,7,IF(P18<Matchup!$B$39+Matchup!$B$40,3,0))) -> 0 | S18: =IF($I18<>$O18,0,IF(Q18<Matchup!$C$39,7,IF(Q18<Matchup!$C$39+Matchup!$C$40,3,0))) -> 0 | T18: =I18+R18 -> 38 | U18: =O18+S18 -> 24 | V18: =T18-U18 -> 14 | W18: =T18+U18 -> 62 | Y18: 1 | Z18: =(COUNTIF($V$4:$V$3003,1)+COUNTIF($V$4:$V$3003,-1))/$Z$4 -> 0.055333333 | AA18: 2.5%
A19: 16 | B19: =NORMINV(RAND(),1,Coefficients!$B$22) -> 1.1351155 | C19: =MEDIAN(8,16,ROUND(NORMINV(RAND(),Coefficients!$B$20,Coefficients!$B$21),0)) -> 11 | D19: =CRITBINOM($C19,MIN(0.75,Matchup!$B$39*$B19),RAND()) -> 1 | E19: =CRITBINOM(D19,Coefficients!$B$30,RAND()) -> 0 | F19: =CRITBINOM(E19,Coefficients!$B$31,RAND()) -> 0 | G19: =CRITBINOM(MAX(0,D19-E19),1-Coefficients!$B$32,RAND()) -> 0 | H19: =CRITBINOM(MAX(0,$C19-D19),MIN(0.6,Matchup!$B$40*SQRT($B19)/(1-MIN(0.75,Matchup!$B$39*$B19))),RAND()) -> 2 | I19: =6*D19+(D19-E19-G19)+2*F19+3*H19 -> 13 | J19: =CRITBINOM($C19,MIN(0.75,Matchup!$C$39*$B19),RAND()) -> 1 | K19: =CRITBINOM(J19,Coefficients!$B$30,RAND()) -> 0 | L19: =CRITBINOM(K19,Coefficients!$B$31,RAND()) -> 0 | M19: =CRITBINOM(MAX(0,J19-K19),1-Coefficients!$B$32,RAND()) -> 0 | N19: =CRITBINOM(MAX(0,$C19-J19),MIN(0.6,Matchup!$C$40*SQRT($B19)/(1-MIN(0.75,Matchup!$C$39*$B19))),RAND()) -> 2 | O19: =6*J19+(J19-K19-M19)+2*L19+3*N19 -> 13 | P19: =RAND() -> 0.91809682 | Q19: =RAND() -> 0.040367418 | R19: =IF($I19<>$O19,0,IF(P19<Matchup!$B$39,7,IF(P19<Matchup!$B$39+Matchup!$B$40,3,0))) -> 0 | S19: =IF($I19<>$O19,0,IF(Q19<Matchup!$C$39,7,IF(Q19<Matchup!$C$39+Matchup!$C$40,3,0))) -> 7 | T19: =I19+R19 -> 13 | U19: =O19+S19 -> 20 | V19: =T19-U19 -> -7 | W19: =T19+U19 -> 33 | Y19: 3 | Z19: =(COUNTIF($V$4:$V$3003,3)+COUNTIF($V$4:$V$3003,-3))/$Z$4 -> 0.077666667 | AA19: 9.5% - the most common margin in football
A20: 17 | B20: =NORMINV(RAND(),1,Coefficients!$B$22) -> 1.0042369 | C20: =MEDIAN(8,16,ROUND(NORMINV(RAND(),Coefficients!$B$20,Coefficients!$B$21),0)) -> 11 | D20: =CRITBINOM($C20,MIN(0.75,Matchup!$B$39*$B20),RAND()) -> 1 | E20: =CRITBINOM(D20,Coefficients!$B$30,RAND()) -> 0 | F20: =CRITBINOM(E20,Coefficients!$B$31,RAND()) -> 0 | G20: =CRITBINOM(MAX(0,D20-E20),1-Coefficients!$B$32,RAND()) -> 0 | H20: =CRITBINOM(MAX(0,$C20-D20),MIN(0.6,Matchup!$B$40*SQRT($B20)/(1-MIN(0.75,Matchup!$B$39*$B20))),RAND()) -> 2 | I20: =6*D20+(D20-E20-G20)+2*F20+3*H20 -> 13 | J20: =CRITBINOM($C20,MIN(0.75,Matchup!$C$39*$B20),RAND()) -> 6 | K20: =CRITBINOM(J20,Coefficients!$B$30,RAND()) -> 0 | L20: =CRITBINOM(K20,Coefficients!$B$31,RAND()) -> 0 | M20: =CRITBINOM(MAX(0,J20-K20),1-Coefficients!$B$32,RAND()) -> 1 | N20: =CRITBINOM(MAX(0,$C20-J20),MIN(0.6,Matchup!$C$40*SQRT($B20)/(1-MIN(0.75,Matchup!$C$39*$B20))),RAND()) -> 1 | O20: =6*J20+(J20-K20-M20)+2*L20+3*N20 -> 44 | P20: =RAND() -> 0.095953269 | Q20: =RAND() -> 0.97043073 | R20: =IF($I20<>$O20,0,IF(P20<Matchup!$B$39,7,IF(P20<Matchup!$B$39+Matchup!$B$40,3,0))) -> 0 | S20: =IF($I20<>$O20,0,IF(Q20<Matchup!$C$39,7,IF(Q20<Matchup!$C$39+Matchup!$C$40,3,0))) -> 0 | T20: =I20+R20 -> 13 | U20: =O20+S20 -> 44 | V20: =T20-U20 -> -31 | W20: =T20+U20 -> 57 | Y20: 4 | Z20: =(COUNTIF($V$4:$V$3003,4)+COUNTIF($V$4:$V$3003,-4))/$Z$4 -> 0.061666667 | AA20: 4.9%
A21: 18 | B21: =NORMINV(RAND(),1,Coefficients!$B$22) -> 0.96449116 | C21: =MEDIAN(8,16,ROUND(NORMINV(RAND(),Coefficients!$B$20,Coefficients!$B$21),0)) -> 11 | D21: =CRITBINOM($C21,MIN(0.75,Matchup!$B$39*$B21),RAND()) -> 2 | E21: =CRITBINOM(D21,Coefficients!$B$30,RAND()) -> 1 | F21: =CRITBINOM(E21,Coefficients!$B$31,RAND()) -> 1 | G21: =CRITBINOM(MAX(0,D21-E21),1-Coefficients!$B$32,RAND()) -> 0 | H21: =CRITBINOM(MAX(0,$C21-D21),MIN(0.6,Matchup!$B$40*SQRT($B21)/(1-MIN(0.75,Matchup!$B$39*$B21))),RAND()) -> 0 | I21: =6*D21+(D21-E21-G21)+2*F21+3*H21 -> 15 | J21: =CRITBINOM($C21,MIN(0.75,Matchup!$C$39*$B21),RAND()) -> 1 | K21: =CRITBINOM(J21,Coefficients!$B$30,RAND()) -> 0 | L21: =CRITBINOM(K21,Coefficients!$B$31,RAND()) -> 0 | M21: =CRITBINOM(MAX(0,J21-K21),1-Coefficients!$B$32,RAND()) -> 0 | N21: =CRITBINOM(MAX(0,$C21-J21),MIN(0.6,Matchup!$C$40*SQRT($B21)/(1-MIN(0.75,Matchup!$C$39*$B21))),RAND()) -> 2 | O21: =6*J21+(J21-K21-M21)+2*L21+3*N21 -> 13 | P21: =RAND() -> 0.21731749 | Q21: =RAND() -> 0.25092236 | R21: =IF($I21<>$O21,0,IF(P21<Matchup!$B$39,7,IF(P21<Matchup!$B$39+Matchup!$B$40,3,0))) -> 0 | S21: =IF($I21<>$O21,0,IF(Q21<Matchup!$C$39,7,IF(Q21<Matchup!$C$39+Matchup!$C$40,3,0))) -> 0 | T21: =I21+R21 -> 15 | U21: =O21+S21 -> 13 | V21: =T21-U21 -> 2 | W21: =T21+U21 -> 28 | Y21: 6 | Z21: =(COUNTIF($V$4:$V$3003,6)+COUNTIF($V$4:$V$3003,-6))/$Z$4 -> 0.049 | AA21: 5.3%
A22: 19 | B22: =NORMINV(RAND(),1,Coefficients!$B$22) -> 1.0622548 | C22: =MEDIAN(8,16,ROUND(NORMINV(RAND(),Coefficients!$B$20,Coefficients!$B$21),0)) -> 11 | D22: =CRITBINOM($C22,MIN(0.75,Matchup!$B$39*$B22),RAND()) -> 4 | E22: =CRITBINOM(D22,Coefficients!$B$30,RAND()) -> 2 | F22: =CRITBINOM(E22,Coefficients!$B$31,RAND()) -> 1 | G22: =CRITBINOM(MAX(0,D22-E22),1-Coefficients!$B$32,RAND()) -> 0 | H22: =CRITBINOM(MAX(0,$C22-D22),MIN(0.6,Matchup!$B$40*SQRT($B22)/(1-MIN(0.75,Matchup!$B$39*$B22))),RAND()) -> 1 | I22: =6*D22+(D22-E22-G22)+2*F22+3*H22 -> 31 | J22: =CRITBINOM($C22,MIN(0.75,Matchup!$C$39*$B22),RAND()) -> 4 | K22: =CRITBINOM(J22,Coefficients!$B$30,RAND()) -> 0 | L22: =CRITBINOM(K22,Coefficients!$B$31,RAND()) -> 0 | M22: =CRITBINOM(MAX(0,J22-K22),1-Coefficients!$B$32,RAND()) -> 1 | N22: =CRITBINOM(MAX(0,$C22-J22),MIN(0.6,Matchup!$C$40*SQRT($B22)/(1-MIN(0.75,Matchup!$C$39*$B22))),RAND()) -> 2 | O22: =6*J22+(J22-K22-M22)+2*L22+3*N22 -> 33 | P22: =RAND() -> 0.082884598 | Q22: =RAND() -> 0.32096435 | R22: =IF($I22<>$O22,0,IF(P22<Matchup!$B$39,7,IF(P22<Matchup!$B$39+Matchup!$B$40,3,0))) -> 0 | S22: =IF($I22<>$O22,0,IF(Q22<Matchup!$C$39,7,IF(Q22<Matchup!$C$39+Matchup!$C$40,3,0))) -> 0 | T22: =I22+R22 -> 31 | U22: =O22+S22 -> 33 | V22: =T22-U22 -> -2 | W22: =T22+U22 -> 64 | Y22: 7 | Z22: =(COUNTIF($V$4:$V$3003,7)+COUNTIF($V$4:$V$3003,-7))/$Z$4 -> 0.079333333 | AA22: 7.1% - the second most common
A23: 20 | B23: =NORMINV(RAND(),1,Coefficients!$B$22) -> 0.9370962 | C23: =MEDIAN(8,16,ROUND(NORMINV(RAND(),Coefficients!$B$20,Coefficients!$B$21),0)) -> 11 | D23: =CRITBINOM($C23,MIN(0.75,Matchup!$B$39*$B23),RAND()) -> 3 | E23: =CRITBINOM(D23,Coefficients!$B$30,RAND()) -> 1 | F23: =CRITBINOM(E23,Coefficients!$B$31,RAND()) -> 0 | G23: =CRITBINOM(MAX(0,D23-E23),1-Coefficients!$B$32,RAND()) -> 0 | H23: =CRITBINOM(MAX(0,$C23-D23),MIN(0.6,Matchup!$B$40*SQRT($B23)/(1-MIN(0.75,Matchup!$B$39*$B23))),RAND()) -> 1 | I23: =6*D23+(D23-E23-G23)+2*F23+3*H23 -> 23 | J23: =CRITBINOM($C23,MIN(0.75,Matchup!$C$39*$B23),RAND()) -> 2 | K23: =CRITBINOM(J23,Coefficients!$B$30,RAND()) -> 1 | L23: =CRITBINOM(K23,Coefficients!$B$31,RAND()) -> 0 | M23: =CRITBINOM(MAX(0,J23-K23),1-Coefficients!$B$32,RAND()) -> 0 | N23: =CRITBINOM(MAX(0,$C23-J23),MIN(0.6,Matchup!$C$40*SQRT($B23)/(1-MIN(0.75,Matchup!$C$39*$B23))),RAND()) -> 1 | O23: =6*J23+(J23-K23-M23)+2*L23+3*N23 -> 16 | P23: =RAND() -> 0.48539496 | Q23: =RAND() -> 0.089198065 | R23: =IF($I23<>$O23,0,IF(P23<Matchup!$B$39,7,IF(P23<Matchup!$B$39+Matchup!$B$40,3,0))) -> 0 | S23: =IF($I23<>$O23,0,IF(Q23<Matchup!$C$39,7,IF(Q23<Matchup!$C$39+Matchup!$C$40,3,0))) -> 0 | T23: =I23+R23 -> 23 | U23: =O23+S23 -> 16 | V23: =T23-U23 -> 7 | W23: =T23+U23 -> 39 | Y23: 10 | Z23: =(COUNTIF($V$4:$V$3003,10)+COUNTIF($V$4:$V$3003,-10))/$Z$4 -> 0.065 | AA23: 5.7%
A24: 21 | B24: =NORMINV(RAND(),1,Coefficients!$B$22) -> 0.91748044 | C24: =MEDIAN(8,16,ROUND(NORMINV(RAND(),Coefficients!$B$20,Coefficients!$B$21),0)) -> 13 | D24: =CRITBINOM($C24,MIN(0.75,Matchup!$B$39*$B24),RAND()) -> 4 | E24: =CRITBINOM(D24,Coefficients!$B$30,RAND()) -> 0 | F24: =CRITBINOM(E24,Coefficients!$B$31,RAND()) -> 0 | G24: =CRITBINOM(MAX(0,D24-E24),1-Coefficients!$B$32,RAND()) -> 0 | H24: =CRITBINOM(MAX(0,$C24-D24),MIN(0.6,Matchup!$B$40*SQRT($B24)/(1-MIN(0.75,Matchup!$B$39*$B24))),RAND()) -> 5 | I24: =6*D24+(D24-E24-G24)+2*F24+3*H24 -> 43 | J24: =CRITBINOM($C24,MIN(0.75,Matchup!$C$39*$B24),RAND()) -> 2 | K24: =CRITBINOM(J24,Coefficients!$B$30,RAND()) -> 0 | L24: =CRITBINOM(K24,Coefficients!$B$31,RAND()) -> 0 | M24: =CRITBINOM(MAX(0,J24-K24),1-Coefficients!$B$32,RAND()) -> 0 | N24: =CRITBINOM(MAX(0,$C24-J24),MIN(0.6,Matchup!$C$40*SQRT($B24)/(1-MIN(0.75,Matchup!$C$39*$B24))),RAND()) -> 1 | O24: =6*J24+(J24-K24-M24)+2*L24+3*N24 -> 17 | P24: =RAND() -> 0.75583001 | Q24: =RAND() -> 0.082679811 | R24: =IF($I24<>$O24,0,IF(P24<Matchup!$B$39,7,IF(P24<Matchup!$B$39+Matchup!$B$40,3,0))) -> 0 | S24: =IF($I24<>$O24,0,IF(Q24<Matchup!$C$39,7,IF(Q24<Matchup!$C$39+Matchup!$C$40,3,0))) -> 0 | T24: =I24+R24 -> 43 | U24: =O24+S24 -> 17 | V24: =T24-U24 -> 26 | W24: =T24+U24 -> 60 | Y24: 14 | Z24: =(COUNTIF($V$4:$V$3003,14)+COUNTIF($V$4:$V$3003,-14))/$Z$4 -> 0.043333333 | AA24: 4.4%
A25: 22 | B25: =NORMINV(RAND(),1,Coefficients!$B$22) -> 1.0624785 | C25: =MEDIAN(8,16,ROUND(NORMINV(RAND(),Coefficients!$B$20,Coefficients!$B$21),0)) -> 8 | D25: =CRITBINOM($C25,MIN(0.75,Matchup!$B$39*$B25),RAND()) -> 2 | E25: =CRITBINOM(D25,Coefficients!$B$30,RAND()) -> 0 | F25: =CRITBINOM(E25,Coefficients!$B$31,RAND()) -> 0 | G25: =CRITBINOM(MAX(0,D25-E25),1-Coefficients!$B$32,RAND()) -> 0 | H25: =CRITBINOM(MAX(0,$C25-D25),MIN(0.6,Matchup!$B$40*SQRT($B25)/(1-MIN(0.75,Matchup!$B$39*$B25))),RAND()) -> 2 | I25: =6*D25+(D25-E25-G25)+2*F25+3*H25 -> 20 | J25: =CRITBINOM($C25,MIN(0.75,Matchup!$C$39*$B25),RAND()) -> 0 | K25: =CRITBINOM(J25,Coefficients!$B$30,RAND()) -> 0 | L25: =CRITBINOM(K25,Coefficients!$B$31,RAND()) -> 0 | M25: =CRITBINOM(MAX(0,J25-K25),1-Coefficients!$B$32,RAND()) -> 0 | N25: =CRITBINOM(MAX(0,$C25-J25),MIN(0.6,Matchup!$C$40*SQRT($B25)/(1-MIN(0.75,Matchup!$C$39*$B25))),RAND()) -> 1 | O25: =6*J25+(J25-K25-M25)+2*L25+3*N25 -> 3 | P25: =RAND() -> 0.3759975 | Q25: =RAND() -> 0.9534621 | R25: =IF($I25<>$O25,0,IF(P25<Matchup!$B$39,7,IF(P25<Matchup!$B$39+Matchup!$B$40,3,0))) -> 0 | S25: =IF($I25<>$O25,0,IF(Q25<Matchup!$C$39,7,IF(Q25<Matchup!$C$39+Matchup!$C$40,3,0))) -> 0 | T25: =I25+R25 -> 20 | U25: =O25+S25 -> 3 | V25: =T25-U25 -> 17 | W25: =T25+U25 -> 23 | Y25: 17 | Z25: =(COUNTIF($V$4:$V$3003,17)+COUNTIF($V$4:$V$3003,-17))/$Z$4 -> 0.032333333 | AA25: 3.4%
A26: 23 | B26: =NORMINV(RAND(),1,Coefficients!$B$22) -> 0.95636946 | C26: =MEDIAN(8,16,ROUND(NORMINV(RAND(),Coefficients!$B$20,Coefficients!$B$21),0)) -> 11 | D26: =CRITBINOM($C26,MIN(0.75,Matchup!$B$39*$B26),RAND()) -> 4 | E26: =CRITBINOM(D26,Coefficients!$B$30,RAND()) -> 0 | F26: =CRITBINOM(E26,Coefficients!$B$31,RAND()) -> 0 | G26: =CRITBINOM(MAX(0,D26-E26),1-Coefficients!$B$32,RAND()) -> 0 | H26: =CRITBINOM(MAX(0,$C26-D26),MIN(0.6,Matchup!$B$40*SQRT($B26)/(1-MIN(0.75,Matchup!$B$39*$B26))),RAND()) -> 3 | I26: =6*D26+(D26-E26-G26)+2*F26+3*H26 -> 37 | J26: =CRITBINOM($C26,MIN(0.75,Matchup!$C$39*$B26),RAND()) -> 2 | K26: =CRITBINOM(J26,Coefficients!$B$30,RAND()) -> 0 | L26: =CRITBINOM(K26,Coefficients!$B$31,RAND()) -> 0 | M26: =CRITBINOM(MAX(0,J26-K26),1-Coefficients!$B$32,RAND()) -> 0 | N26: =CRITBINOM(MAX(0,$C26-J26),MIN(0.6,Matchup!$C$40*SQRT($B26)/(1-MIN(0.75,Matchup!$C$39*$B26))),RAND()) -> 3 | O26: =6*J26+(J26-K26-M26)+2*L26+3*N26 -> 23 | P26: =RAND() -> 0.591606 | Q26: =RAND() -> 0.7872388 | R26: =IF($I26<>$O26,0,IF(P26<Matchup!$B$39,7,IF(P26<Matchup!$B$39+Matchup!$B$40,3,0))) -> 0 | S26: =IF($I26<>$O26,0,IF(Q26<Matchup!$C$39,7,IF(Q26<Matchup!$C$39+Matchup!$C$40,3,0))) -> 0 | T26: =I26+R26 -> 37 | U26: =O26+S26 -> 23 | V26: =T26-U26 -> 14 | W26: =T26+U26 -> 60
A27: 24 | B27: =NORMINV(RAND(),1,Coefficients!$B$22) -> 0.97644242 | C27: =MEDIAN(8,16,ROUND(NORMINV(RAND(),Coefficients!$B$20,Coefficients!$B$21),0)) -> 11 | D27: =CRITBINOM($C27,MIN(0.75,Matchup!$B$39*$B27),RAND()) -> 2 | E27: =CRITBINOM(D27,Coefficients!$B$30,RAND()) -> 0 | F27: =CRITBINOM(E27,Coefficients!$B$31,RAND()) -> 0 | G27: =CRITBINOM(MAX(0,D27-E27),1-Coefficients!$B$32,RAND()) -> 1 | H27: =CRITBINOM(MAX(0,$C27-D27),MIN(0.6,Matchup!$B$40*SQRT($B27)/(1-MIN(0.75,Matchup!$B$39*$B27))),RAND()) -> 1 | I27: =6*D27+(D27-E27-G27)+2*F27+3*H27 -> 16 | J27: =CRITBINOM($C27,MIN(0.75,Matchup!$C$39*$B27),RAND()) -> 1 | K27: =CRITBINOM(J27,Coefficients!$B$30,RAND()) -> 0 | L27: =CRITBINOM(K27,Coefficients!$B$31,RAND()) -> 0 | M27: =CRITBINOM(MAX(0,J27-K27),1-Coefficients!$B$32,RAND()) -> 0 | N27: =CRITBINOM(MAX(0,$C27-J27),MIN(0.6,Matchup!$C$40*SQRT($B27)/(1-MIN(0.75,Matchup!$C$39*$B27))),RAND()) -> 1 | O27: =6*J27+(J27-K27-M27)+2*L27+3*N27 -> 10 | P27: =RAND() -> 0.53642533 | Q27: =RAND() -> 0.41685625 | R27: =IF($I27<>$O27,0,IF(P27<Matchup!$B$39,7,IF(P27<Matchup!$B$39+Matchup!$B$40,3,0))) -> 0 | S27: =IF($I27<>$O27,0,IF(Q27<Matchup!$C$39,7,IF(Q27<Matchup!$C$39+Matchup!$C$40,3,0))) -> 0 | T27: =I27+R27 -> 16 | U27: =O27+S27 -> 10 | V27: =T27-U27 -> 6 | W27: =T27+U27 -> 26 | Y27: If your model column drifts far from the right-hand column across many matchups, adjust the TD and FG elasticities on the Coefficients sheet.
A28: 25 | B28: =NORMINV(RAND(),1,Coefficients!$B$22) -> 1.091382 | C28: =MEDIAN(8,16,ROUND(NORMINV(RAND(),Coefficients!$B$20,Coefficients!$B$21),0)) -> 11 | D28: =CRITBINOM($C28,MIN(0.75,Matchup!$B$39*$B28),RAND()) -> 3 | E28: =CRITBINOM(D28,Coefficients!$B$30,RAND()) -> 1 | F28: =CRITBINOM(E28,Coefficients!$B$31,RAND()) -> 1 | G28: =CRITBINOM(MAX(0,D28-E28),1-Coefficients!$B$32,RAND()) -> 0 | H28: =CRITBINOM(MAX(0,$C28-D28),MIN(0.6,Matchup!$B$40*SQRT($B28)/(1-MIN(0.75,Matchup!$B$39*$B28))),RAND()) -> 0 | I28: =6*D28+(D28-E28-G28)+2*F28+3*H28 -> 22 | J28: =CRITBINOM($C28,MIN(0.75,Matchup!$C$39*$B28),RAND()) -> 2 | K28: =CRITBINOM(J28,Coefficients!$B$30,RAND()) -> 1 | L28: =CRITBINOM(K28,Coefficients!$B$31,RAND()) -> 1 | M28: =CRITBINOM(MAX(0,J28-K28),1-Coefficients!$B$32,RAND()) -> 0 | N28: =CRITBINOM(MAX(0,$C28-J28),MIN(0.6,Matchup!$C$40*SQRT($B28)/(1-MIN(0.75,Matchup!$C$39*$B28))),RAND()) -> 1 | O28: =6*J28+(J28-K28-M28)+2*L28+3*N28 -> 18 | P28: =RAND() -> 0.36591435 | Q28: =RAND() -> 0.19484212 | R28: =IF($I28<>$O28,0,IF(P28<Matchup!$B$39,7,IF(P28<Matchup!$B$39+Matchup!$B$40,3,0))) -> 0 | S28: =IF($I28<>$O28,0,IF(Q28<Matchup!$C$39,7,IF(Q28<Matchup!$C$39+Matchup!$C$40,3,0))) -> 0 | T28: =I28+R28 -> 22 | U28: =O28+S28 -> 18 | V28: =T28-U28 -> 4 | W28: =T28+U28 -> 40
A29: 26 | B29: =NORMINV(RAND(),1,Coefficients!$B$22) -> 1.0181573 | C29: =MEDIAN(8,16,ROUND(NORMINV(RAND(),Coefficients!$B$20,Coefficients!$B$21),0)) -> 11 | D29: =CRITBINOM($C29,MIN(0.75,Matchup!$B$39*$B29),RAND()) -> 3 | E29: =CRITBINOM(D29,Coefficients!$B$30,RAND()) -> 0 | F29: =CRITBINOM(E29,Coefficients!$B$31,RAND()) -> 0 | G29: =CRITBINOM(MAX(0,D29-E29),1-Coefficients!$B$32,RAND()) -> 0 | H29: =CRITBINOM(MAX(0,$C29-D29),MIN(0.6,Matchup!$B$40*SQRT($B29)/(1-MIN(0.75,Matchup!$B$39*$B29))),RAND()) -> 1 | I29: =6*D29+(D29-E29-G29)+2*F29+3*H29 -> 24 | J29: =CRITBINOM($C29,MIN(0.75,Matchup!$C$39*$B29),RAND()) -> 0 | K29: =CRITBINOM(J29,Coefficients!$B$30,RAND()) -> 0 | L29: =CRITBINOM(K29,Coefficients!$B$31,RAND()) -> 0 | M29: =CRITBINOM(MAX(0,J29-K29),1-Coefficients!$B$32,RAND()) -> 0 | N29: =CRITBINOM(MAX(0,$C29-J29),MIN(0.6,Matchup!$C$40*SQRT($B29)/(1-MIN(0.75,Matchup!$C$39*$B29))),RAND()) -> 2 | O29: =6*J29+(J29-K29-M29)+2*L29+3*N29 -> 6 | P29: =RAND() -> 0.74515865 | Q29: =RAND() -> 0.20243484 | R29: =IF($I29<>$O29,0,IF(P29<Matchup!$B$39,7,IF(P29<Matchup!$B$39+Matchup!$B$40,3,0))) -> 0 | S29: =IF($I29<>$O29,0,IF(Q29<Matchup!$C$39,7,IF(Q29<Matchup!$C$39+Matchup!$C$40,3,0))) -> 0 | T29: =I29+R29 -> 24 | U29: =O29+S29 -> 6 | V29: =T29-U29 -> 18 | W29: =T29+U29 -> 30
A30: 27 | B30: =NORMINV(RAND(),1,Coefficients!$B$22) -> 1.0861663 | C30: =MEDIAN(8,16,ROUND(NORMINV(RAND(),Coefficients!$B$20,Coefficients!$B$21),0)) -> 11 | D30: =CRITBINOM($C30,MIN(0.75,Matchup!$B$39*$B30),RAND()) -> 4 | E30: =CRITBINOM(D30,Coefficients!$B$30,RAND()) -> 0 | F30: =CRITBINOM(E30,Coefficients!$B$31,RAND()) -> 0 | G30: =CRITBINOM(MAX(0,D30-E30),1-Coefficients!$B$32,RAND()) -> 0 | H30: =CRITBINOM(MAX(0,$C30-D30),MIN(0.6,Matchup!$B$40*SQRT($B30)/(1-MIN(0.75,Matchup!$B$39*$B30))),RAND()) -> 0 | I30: =6*D30+(D30-E30-G30)+2*F30+3*H30 -> 28 | J30: =CRITBINOM($C30,MIN(0.75,Matchup!$C$39*$B30),RAND()) -> 4 | K30: =CRITBINOM(J30,Coefficients!$B$30,RAND()) -> 1 | L30: =CRITBINOM(K30,Coefficients!$B$31,RAND()) -> 0 | M30: =CRITBINOM(MAX(0,J30-K30),1-Coefficients!$B$32,RAND()) -> 0 | N30: =CRITBINOM(MAX(0,$C30-J30),MIN(0.6,Matchup!$C$40*SQRT($B30)/(1-MIN(0.75,Matchup!$C$39*$B30))),RAND()) -> 0 | O30: =6*J30+(J30-K30-M30)+2*L30+3*N30 -> 27 | P30: =RAND() -> 0.9740096 | Q30: =RAND() -> 0.21268903 | R30: =IF($I30<>$O30,0,IF(P30<Matchup!$B$39,7,IF(P30<Matchup!$B$39+Matchup!$B$40,3,0))) -> 0 | S30: =IF($I30<>$O30,0,IF(Q30<Matchup!$C$39,7,IF(Q30<Matchup!$C$39+Matchup!$C$40,3,0))) -> 0 | T30: =I30+R30 -> 28 | U30: =O30+S30 -> 27 | V30: =T30-U30 -> 1 | W30: =T30+U30 -> 55
A31: 28 | B31: =NORMINV(RAND(),1,Coefficients!$B$22) -> 1.0083645 | C31: =MEDIAN(8,16,ROUND(NORMINV(RAND(),Coefficients!$B$20,Coefficients!$B$21),0)) -> 12 | D31: =CRITBINOM($C31,MIN(0.75,Matchup!$B$39*$B31),RAND()) -> 6 | E31: =CRITBINOM(D31,Coefficients!$B$30,RAND()) -> 1 | F31: =CRITBINOM(E31,Coefficients!$B$31,RAND()) -> 0 | G31: =CRITBINOM(MAX(0,D31-E31),1-Coefficients!$B$32,RAND()) -> 0 | H31: =CRITBINOM(MAX(0,$C31-D31),MIN(0.6,Matchup!$B$40*SQRT($B31)/(1-MIN(0.75,Matchup!$B$39*$B31))),RAND()) -> 0 | I31: =6*D31+(D31-E31-G31)+2*F31+3*H31 -> 41 | J31: =CRITBINOM($C31,MIN(0.75,Matchup!$C$39*$B31),RAND()) -> 4 | K31: =CRITBINOM(J31,Coefficients!$B$30,RAND()) -> 1 | L31: =CRITBINOM(K31,Coefficients!$B$31,RAND()) -> 1 | M31: =CRITBINOM(MAX(0,J31-K31),1-Coefficients!$B$32,RAND()) -> 0 | N31: =CRITBINOM(MAX(0,$C31-J31),MIN(0.6,Matchup!$C$40*SQRT($B31)/(1-MIN(0.75,Matchup!$C$39*$B31))),RAND()) -> 1 | O31: =6*J31+(J31-K31-M31)+2*L31+3*N31 -> 32 | P31: =RAND() -> 0.59482963 | Q31: =RAND() -> 0.38945433 | R31: =IF($I31<>$O31,0,IF(P31<Matchup!$B$39,7,IF(P31<Matchup!$B$39+Matchup!$B$40,3,0))) -> 0 | S31: =IF($I31<>$O31,0,IF(Q31<Matchup!$C$39,7,IF(Q31<Matchup!$C$39+Matchup!$C$40,3,0))) -> 0 | T31: =I31+R31 -> 41 | U31: =O31+S31 -> 32 | V31: =T31-U31 -> 9 | W31: =T31+U31 -> 73
A32: 29 | B32: =NORMINV(RAND(),1,Coefficients!$B$22) -> 1.0160061 | C32: =MEDIAN(8,16,ROUND(NORMINV(RAND(),Coefficients!$B$20,Coefficients!$B$21),0)) -> 13 | D32: =CRITBINOM($C32,MIN(0.75,Matchup!$B$39*$B32),RAND()) -> 3 | E32: =CRITBINOM(D32,Coefficients!$B$30,RAND()) -> 0 | F32: =CRITBINOM(E32,Coefficients!$B$31,RAND()) -> 0 | G32: =CRITBINOM(MAX(0,D32-E32),1-Coefficients!$B$32,RAND()) -> 0 | H32: =CRITBINOM(MAX(0,$C32-D32),MIN(0.6,Matchup!$B$40*SQRT($B32)/(1-MIN(0.75,Matchup!$B$39*$B32))),RAND()) -> 1 | I32: =6*D32+(D32-E32-G32)+2*F32+3*H32 -> 24 | J32: =CRITBINOM($C32,MIN(0.75,Matchup!$C$39*$B32),RAND()) -> 2 | K32: =CRITBINOM(J32,Coefficients!$B$30,RAND()) -> 0 | L32: =CRITBINOM(K32,Coefficients!$B$31,RAND()) -> 0 | M32: =CRITBINOM(MAX(0,J32-K32),1-Coefficients!$B$32,RAND()) -> 1 | N32: =CRITBINOM(MAX(0,$C32-J32),MIN(0.6,Matchup!$C$40*SQRT($B32)/(1-MIN(0.75,Matchup!$C$39*$B32))),RAND()) -> 2 | O32: =6*J32+(J32-K32-M32)+2*L32+3*N32 -> 19 | P32: =RAND() -> 0.53893691 | Q32: =RAND() -> 0.9958275 | R32: =IF($I32<>$O32,0,IF(P32<Matchup!$B$39,7,IF(P32<Matchup!$B$39+Matchup!$B$40,3,0))) -> 0 | S32: =IF($I32<>$O32,0,IF(Q32<Matchup!$C$39,7,IF(Q32<Matchup!$C$39+Matchup!$C$40,3,0))) -> 0 | T32: =I32+R32 -> 24 | U32: =O32+S32 -> 19 | V32: =T32-U32 -> 5 | W32: =T32+U32 -> 43
A33: 30 | B33: =NORMINV(RAND(),1,Coefficients!$B$22) -> 0.81137936 | C33: =MEDIAN(8,16,ROUND(NORMINV(RAND(),Coefficients!$B$20,Coefficients!$B$21),0)) -> 10 | D33: =CRITBINOM($C33,MIN(0.75,Matchup!$B$39*$B33),RAND()) -> 3 | E33: =CRITBINOM(D33,Coefficients!$B$30,RAND()) -> 0 | F33: =CRITBINOM(E33,Coefficients!$B$31,RAND()) -> 0 | G33: =CRITBINOM(MAX(0,D33-E33),1-Coefficients!$B$32,RAND()) -> 0 | H33: =CRITBINOM(MAX(0,$C33-D33),MIN(0.6,Matchup!$B$40*SQRT($B33)/(1-MIN(0.75,Matchup!$B$39*$B33))),RAND()) -> 3 | I33: =6*D33+(D33-E33-G33)+2*F33+3*H33 -> 30 | J33: =CRITBINOM($C33,MIN(0.75,Matchup!$C$39*$B33),RAND()) -> 1 | K33: =CRITBINOM(J33,Coefficients!$B$30,RAND()) -> 0 | L33: =CRITBINOM(K33,Coefficients!$B$31,RAND()) -> 0 | M33: =CRITBINOM(MAX(0,J33-K33),1-Coefficients!$B$32,RAND()) -> 0 | N33: =CRITBINOM(MAX(0,$C33-J33),MIN(0.6,Matchup!$C$40*SQRT($B33)/(1-MIN(0.75,Matchup!$C$39*$B33))),RAND()) -> 0 | O33: =6*J33+(J33-K33-M33)+2*L33+3*N33 -> 7 | P33: =RAND() -> 0.34951788 | Q33: =RAND() -> 0.040440413 | R33: =IF($I33<>$O33,0,IF(P33<Matchup!$B$39,7,IF(P33<Matchup!$B$39+Matchup!$B$40,3,0))) -> 0 | S33: =IF($I33<>$O33,0,IF(Q33<Matchup!$C$39,7,IF(Q33<Matchup!$C$39+Matchup!$C$40,3,0))) -> 0 | T33: =I33+R33 -> 30 | U33: =O33+S33 -> 7 | V33: =T33-U33 -> 23 | W33: =T33+U33 -> 37
A34: 31 | B34: =NORMINV(RAND(),1,Coefficients!$B$22) -> 1.0343211 | C34: =MEDIAN(8,16,ROUND(NORMINV(RAND(),Coefficients!$B$20,Coefficients!$B$21),0)) -> 11 | D34: =CRITBINOM($C34,MIN(0.75,Matchup!$B$39*$B34),RAND()) -> 0 | E34: =CRITBINOM(D34,Coefficients!$B$30,RAND()) -> 0 | F34: =CRITBINOM(E34,Coefficients!$B$31,RAND()) -> 0 | G34: =CRITBINOM(MAX(0,D34-E34),1-Coefficients!$B$32,RAND()) -> 0 | H34: =CRITBINOM(MAX(0,$C34-D34),MIN(0.6,Matchup!$B$40*SQRT($B34)/(1-MIN(0.75,Matchup!$B$39*$B34))),RAND()) -> 2 | I34: =6*D34+(D34-E34-G34)+2*F34+3*H34 -> 6 | J34: =CRITBINOM($C34,MIN(0.75,Matchup!$C$39*$B34),RAND()) -> 1 | K34: =CRITBINOM(J34,Coefficients!$B$30,RAND()) -> 1 | L34: =CRITBINOM(K34,Coefficients!$B$31,RAND()) -> 1 | M34: =CRITBINOM(MAX(0,J34-K34),1-Coefficients!$B$32,RAND()) -> 0 | N34: =CRITBINOM(MAX(0,$C34-J34),MIN(0.6,Matchup!$C$40*SQRT($B34)/(1-MIN(0.75,Matchup!$C$39*$B34))),RAND()) -> 3 | O34: =6*J34+(J34-K34-M34)+2*L34+3*N34 -> 17 | P34: =RAND() -> 0.64413377 | Q34: =RAND() -> 0.4702565 | R34: =IF($I34<>$O34,0,IF(P34<Matchup!$B$39,7,IF(P34<Matchup!$B$39+Matchup!$B$40,3,0))) -> 0 | S34: =IF($I34<>$O34,0,IF(Q34<Matchup!$C$39,7,IF(Q34<Matchup!$C$39+Matchup!$C$40,3,0))) -> 0 | T34: =I34+R34 -> 6 | U34: =O34+S34 -> 17 | V34: =T34-U34 -> -11 | W34: =T34+U34 -> 23
A35: 32 | B35: =NORMINV(RAND(),1,Coefficients!$B$22) -> 1.0920184 | C35: =MEDIAN(8,16,ROUND(NORMINV(RAND(),Coefficients!$B$20,Coefficients!$B$21),0)) -> 10 | D35: =CRITBINOM($C35,MIN(0.75,Matchup!$B$39*$B35),RAND()) -> 1 | E35: =CRITBINOM(D35,Coefficients!$B$30,RAND()) -> 0 | F35: =CRITBINOM(E35,Coefficients!$B$31,RAND()) -> 0 | G35: =CRITBINOM(MAX(0,D35-E35),1-Coefficients!$B$32,RAND()) -> 0 | H35: =CRITBINOM(MAX(0,$C35-D35),MIN(0.6,Matchup!$B$40*SQRT($B35)/(1-MIN(0.75,Matchup!$B$39*$B35))),RAND()) -> 2 | I35: =6*D35+(D35-E35-G35)+2*F35+3*H35 -> 13 | J35: =CRITBINOM($C35,MIN(0.75,Matchup!$C$39*$B35),RAND()) -> 4 | K35: =CRITBINOM(J35,Coefficients!$B$30,RAND()) -> 0 | L35: =CRITBINOM(K35,Coefficients!$B$31,RAND()) -> 0 | M35: =CRITBINOM(MAX(0,J35-K35),1-Coefficients!$B$32,RAND()) -> 0 | N35: =CRITBINOM(MAX(0,$C35-J35),MIN(0.6,Matchup!$C$40*SQRT($B35)/(1-MIN(0.75,Matchup!$C$39*$B35))),RAND()) -> 0 | O35: =6*J35+(J35-K35-M35)+2*L35+3*N35 -> 28 | P35: =RAND() -> 0.87654508 | Q35: =RAND() -> 0.65778827 | R35: =IF($I35<>$O35,0,IF(P35<Matchup!$B$39,7,IF(P35<Matchup!$B$39+Matchup!$B$40,3,0))) -> 0 | S35: =IF($I35<>$O35,0,IF(Q35<Matchup!$C$39,7,IF(Q35<Matchup!$C$39+Matchup!$C$40,3,0))) -> 0 | T35: =I35+R35 -> 13 | U35: =O35+S35 -> 28 | V35: =T35-U35 -> -15 | W35: =T35+U35 -> 41
A36: 33 | B36: =NORMINV(RAND(),1,Coefficients!$B$22) -> 0.94327267 | C36: =MEDIAN(8,16,ROUND(NORMINV(RAND(),Coefficients!$B$20,Coefficients!$B$21),0)) -> 12 | D36: =CRITBINOM($C36,MIN(0.75,Matchup!$B$39*$B36),RAND()) -> 2 | E36: =CRITBINOM(D36,Coefficients!$B$30,RAND()) -> 0 | F36: =CRITBINOM(E36,Coefficients!$B$31,RAND()) -> 0 | G36: =CRITBINOM(MAX(0,D36-E36),1-Coefficients!$B$32,RAND()) -> 0 | H36: =CRITBINOM(MAX(0,$C36-D36),MIN(0.6,Matchup!$B$40*SQRT($B36)/(1-MIN(0.75,Matchup!$B$39*$B36))),RAND()) -> 1 | I36: =6*D36+(D36-E36-G36)+2*F36+3*H36 -> 17 | J36: =CRITBINOM($C36,MIN(0.75,Matchup!$C$39*$B36),RAND()) -> 4 | K36: =CRITBINOM(J36,Coefficients!$B$30,RAND()) -> 0 | L36: =CRITBINOM(K36,Coefficients!$B$31,RAND()) -> 0 | M36: =CRITBINOM(MAX(0,J36-K36),1-Coefficients!$B$32,RAND()) -> 0 | N36: =CRITBINOM(MAX(0,$C36-J36),MIN(0.6,Matchup!$C$40*SQRT($B36)/(1-MIN(0.75,Matchup!$C$39*$B36))),RAND()) -> 1 | O36: =6*J36+(J36-K36-M36)+2*L36+3*N36 -> 31 | P36: =RAND() -> 0.55749381 | Q36: =RAND() -> 0.78911233 | R36: =IF($I36<>$O36,0,IF(P36<Matchup!$B$39,7,IF(P36<Matchup!$B$39+Matchup!$B$40,3,0))) -> 0 | S36: =IF($I36<>$O36,0,IF(Q36<Matchup!$C$39,7,IF(Q36<Matchup!$C$39+Matchup!$C$40,3,0))) -> 0 | T36: =I36+R36 -> 17 | U36: =O36+S36 -> 31 | V36: =T36-U36 -> -14 | W36: =T36+U36 -> 48
A37: 34 | B37: =NORMINV(RAND(),1,Coefficients!$B$22) -> 0.92542447 | C37: =MEDIAN(8,16,ROUND(NORMINV(RAND(),Coefficients!$B$20,Coefficients!$B$21),0)) -> 11 | D37: =CRITBINOM($C37,MIN(0.75,Matchup!$B$39*$B37),RAND()) -> 2 | E37: =CRITBINOM(D37,Coefficients!$B$30,RAND()) -> 0 | F37: =CRITBINOM(E37,Coefficients!$B$31,RAND()) -> 0 | G37: =CRITBINOM(MAX(0,D37-E37),1-Coefficients!$B$32,RAND()) -> 0 | H37: =CRITBINOM(MAX(0,$C37-D37),MIN(0.6,Matchup!$B$40*SQRT($B37)/(1-MIN(0.75,Matchup!$B$39*$B37))),RAND()) -> 1 | I37: =6*D37+(D37-E37-G37)+2*F37+3*H37 -> 17 | J37: =CRITBINOM($C37,MIN(0.75,Matchup!$C$39*$B37),RAND()) -> 1 | K37: =CRITBINOM(J37,Coefficients!$B$30,RAND()) -> 0 | L37: =CRITBINOM(K37,Coefficients!$B$31,RAND()) -> 0 | M37: =CRITBINOM(MAX(0,J37-K37),1-Coefficients!$B$32,RAND()) -> 0 | N37: =CRITBINOM(MAX(0,$C37-J37),MIN(0.6,Matchup!$C$40*SQRT($B37)/(1-MIN(0.75,Matchup!$C$39*$B37))),RAND()) -> 1 | O37: =6*J37+(J37-K37-M37)+2*L37+3*N37 -> 10 | P37: =RAND() -> 0.1254051 | Q37: =RAND() -> 0.3403746 | R37: =IF($I37<>$O37,0,IF(P37<Matchup!$B$39,7,IF(P37<Matchup!$B$39+Matchup!$B$40,3,0))) -> 0 | S37: =IF($I37<>$O37,0,IF(Q37<Matchup!$C$39,7,IF(Q37<Matchup!$C$39+Matchup!$C$40,3,0))) -> 0 | T37: =I37+R37 -> 17 | U37: =O37+S37 -> 10 | V37: =T37-U37 -> 7 | W37: =T37+U37 -> 27
A38: 35 | B38: =NORMINV(RAND(),1,Coefficients!$B$22) -> 1.046728 | C38: =MEDIAN(8,16,ROUND(NORMINV(RAND(),Coefficients!$B$20,Coefficients!$B$21),0)) -> 10 | D38: =CRITBINOM($C38,MIN(0.75,Matchup!$B$39*$B38),RAND()) -> 3 | E38: =CRITBINOM(D38,Coefficients!$B$30,RAND()) -> 1 | F38: =CRITBINOM(E38,Coefficients!$B$31,RAND()) -> 1 | G38: =CRITBINOM(MAX(0,D38-E38),1-Coefficients!$B$32,RAND()) -> 0 | H38: =CRITBINOM(MAX(0,$C38-D38),MIN(0.6,Matchup!$B$40*SQRT($B38)/(1-MIN(0.75,Matchup!$B$39*$B38))),RAND()) -> 3 | I38: =6*D38+(D38-E38-G38)+2*F38+3*H38 -> 31 | J38: =CRITBINOM($C38,MIN(0.75,Matchup!$C$39*$B38),RAND()) -> 2 | K38: =CRITBINOM(J38,Coefficients!$B$30,RAND()) -> 0 | L38: =CRITBINOM(K38,Coefficients!$B$31,RAND()) -> 0 | M38: =CRITBINOM(MAX(0,J38-K38),1-Coefficients!$B$32,RAND()) -> 0 | N38: =CRITBINOM(MAX(0,$C38-J38),MIN(0.6,Matchup!$C$40*SQRT($B38)/(1-MIN(0.75,Matchup!$C$39*$B38))),RAND()) -> 4 | O38: =6*J38+(J38-K38-M38)+2*L38+3*N38 -> 26 | P38: =RAND() -> 0.84923722 | Q38: =RAND() -> 0.2133962 | R38: =IF($I38<>$O38,0,IF(P38<Matchup!$B$39,7,IF(P38<Matchup!$B$39+Matchup!$B$40,3,0))) -> 0 | S38: =IF($I38<>$O38,0,IF(Q38<Matchup!$C$39,7,IF(Q38<Matchup!$C$39+Matchup!$C$40,3,0))) -> 0 | T38: =I38+R38 -> 31 | U38: =O38+S38 -> 26 | V38: =T38-U38 -> 5 | W38: =T38+U38 -> 57
A39: 36 | B39: =NORMINV(RAND(),1,Coefficients!$B$22) -> 0.9397369 | C39: =MEDIAN(8,16,ROUND(NORMINV(RAND(),Coefficients!$B$20,Coefficients!$B$21),0)) -> 12 | D39: =CRITBINOM($C39,MIN(0.75,Matchup!$B$39*$B39),RAND()) -> 5 | E39: =CRITBINOM(D39,Coefficients!$B$30,RAND()) -> 2 | F39: =CRITBINOM(E39,Coefficients!$B$31,RAND()) -> 2 | G39: =CRITBINOM(MAX(0,D39-E39),1-Coefficients!$B$32,RAND()) -> 0 | H39: =CRITBINOM(MAX(0,$C39-D39),MIN(0.6,Matchup!$B$40*SQRT($B39)/(1-MIN(0.75,Matchup!$B$39*$B39))),RAND()) -> 0 | I39: =6*D39+(D39-E39-G39)+2*F39+3*H39 -> 37 | J39: =CRITBINOM($C39,MIN(0.75,Matchup!$C$39*$B39),RAND()) -> 1 | K39: =CRITBINOM(J39,Coefficients!$B$30,RAND()) -> 0 | L39: =CRITBINOM(K39,Coefficients!$B$31,RAND()) -> 0 | M39: =CRITBINOM(MAX(0,J39-K39),1-Coefficients!$B$32,RAND()) -> 0 | N39: =CRITBINOM(MAX(0,$C39-J39),MIN(0.6,Matchup!$C$40*SQRT($B39)/(1-MIN(0.75,Matchup!$C$39*$B39))),RAND()) -> 2 | O39: =6*J39+(J39-K39-M39)+2*L39+3*N39 -> 13 | P39: =RAND() -> 0.91665763 | Q39: =RAND() -> 0.47047752 | R39: =IF($I39<>$O39,0,IF(P39<Matchup!$B$39,7,IF(P39<Matchup!$B$39+Matchup!$B$40,3,0))) -> 0 | S39: =IF($I39<>$O39,0,IF(Q39<Matchup!$C$39,7,IF(Q39<Matchup!$C$39+Matchup!$C$40,3,0))) -> 0 | T39: =I39+R39 -> 37 | U39: =O39+S39 -> 13 | V39: =T39-U39 -> 24 | W39: =T39+U39 -> 50
